Workbook

Sheet Esquema
A1: Mundial 2026 - Esquema del archivo
A3: Hoja | B3: Descripcion
A4: Grupo A..L | B4: FUENTE DE VERDAD. Editar los goles directamente en las celdas amarillas.
B5: La tabla de posiciones de ese grupo se recalcula al ingresar el resultado.
B6: Las fechas y horarios estan en hora Argentina (UTC-3).
A7: Partidos | B7: Vista consolidada de todos los partidos de grupos (read-only para goles).
B8: Incluye columna 'Hora (ARG)' con el kickoff. Columnas CeldaGolesLocal/CeldaGolesVisitante: direcciones para Elixir.
A9: Eliminatorias | B9: Bracket completo (R32, R16, Cuartos, Semis, 3er Puesto, Final).
B10: Goles editables en cada partido. El ganador se propaga al siguiente cruce automaticamente.
B11: Columna 'Override' (azul): en caso de empate (penales/prorroga), escribir ahi el equipo ganador.
B12: Incluye fecha y hora (ARG) de cada partido.
A13: Esquema | B13: Esta hoja.
A15: Como editar
A16: Desde la app de Excel/LibreOffice | B16: Abrir 'Grupo X', escribir goles en columnas C y E (amarillas), filas 5..10.
A17: Desde Elixir | B17: Cada fila en hoja 'Partidos' incluye CeldaGolesLocal y CeldaGolesVisitante,
B18: que son la direccion exacta (ej: 'Grupo J!C5') donde escribir.
A20: Esquema (hoja Partidos)
A21: MatchID | B21: Identificador estable. Formato 'A1'..'L6'. Clave para Elixir.
A22: Grupo | B22: Letra del grupo (A-L).
A23: Fecha | B23: YYYY-MM-DD.
A24: Local / Visitante | B24: Texto del equipo.
A25: GolesLocal / GolesVisitante | B25: ENTEROS. Calculado desde la hoja del grupo. Vacio = no jugado.
A26: Resultado | B26: 'L' (gana local), 'V' (gana visitante), 'E' (empate), '' (sin jugar).
A27: Sede | B27: Estadio y ciudad.
A28: CeldaGolesLocal | B28: Direccion absoluta (Hoja!Celda) donde Elixir debe escribir GolesLocal.
A29: CeldaGolesVisitante | B29: Direccion absoluta (Hoja!Celda) donde Elixir debe escribir GolesVisitante.
A30: Finalizado | B30: TRUE/FALSE. Calculado: TRUE cuando ambos goles ya estan cargados.
A32: Consumo desde Elixir
A33: Lectura | B33: Abrir el .xlsx, leer hoja 'Partidos'. Goles ya calculados.
A34: Escritura | B34: Para registrar un resultado: tomar MatchID, leer la fila en 'Partidos', usar CeldaGolesLocal
B35: y CeldaGolesVisitante para saber donde escribir. Ej: 'Grupo J!C5' = celda C5 de la hoja 'Grupo J'.
A36: Librerias | B36: Lectura: xlsx_reader o :exoffice. Escritura preservando formulas es complicada;
B37: mas simple: mantener estado en Elixir (BD/struct) y regenerar el xlsx cuando se necesita visualizar.
A38: Tabla nombrada | B38: Hoja Partidos contiene la tabla Excel 'tbl_Partidos' (facilita el parsing).

Sheet Partidos
A1: MatchID | B1: Grupo | C1: Fecha | D1: Hora (ARG) | E1: Local | F1: GolesLocal | G1: GolesVisitante | H1: Visitante | I1: Resultado | J1: Sede | K1: CeldaGolesLocal | L1: CeldaGolesVisitante | M1: Finalizado
A2: A1 | B2: A | C2: 2026-06-11 | D2: 16:00 | E2: Mexico | F2: =IF('Grupo A'!D5="","",'Grupo A'!D5) -> 1 | G2: =IF('Grupo A'!F5="","",'Grupo A'!F5) -> 2 | H2: Sudafrica | I2: =IF(OR(F2="",G2=""),"",IF(F2>G2,"L",IF(F2<G2,"V","E"))) -> V | J2: Estadio Azteca, CDMX | K2: Grupo A!D5 | L2: Grupo A!F5 | M2: =AND(ISNUMBER(F2),ISNUMBER(G2)) -> TRUE
A3: A2 | B3: A | C3: 2026-06-11 | D3: 23:00 | E3: Corea del Sur | F3: =IF('Grupo A'!D6="","",'Grupo A'!D6) -> 3 | G3: =IF('Grupo A'!F6="","",'Grupo A'!F6) -> 4 | H3: Chequia | I3: =IF(OR(F3="",G3=""),"",IF(F3>G3,"L",IF(F3<G3,"V","E"))) -> V | J3: Estadio Akron, Guadalajara | K3: Grupo A!D6 | L3: Grupo A!F6 | M3: =AND(ISNUMBER(F3),ISNUMBER(G3)) -> TRUE
A4: B1 | B4: B | C4: 2026-06-12 | D4: 16:00 | E4: Canada | F4: =IF('Grupo B'!D5="","",'Grupo B'!D5) -> 1 | G4: =IF('Grupo B'!F5="","",'Grupo B'!F5) -> 2 | H4: Bosnia y Herzegovina | I4: =IF(OR(F4="",G4=""),"",IF(F4>G4,"L",IF(F4<G4,"V","E"))) -> V | J4: BMO Field, Toronto | K4: Grupo B!D5 | L4: Grupo B!F5 | M4: =AND(ISNUMBER(F4),ISNUMBER(G4)) -> TRUE
A5: D1 | B5: D | C5: 2026-06-12 | D5: 22:00 | E5: Estados Unidos | F5: =IF('Grupo D'!D5="","",'Grupo D'!D5) | G5: =IF('Grupo D'!F5="","",'Grupo D'!F5) | H5: Paraguay | I5: =IF(OR(F5="",G5=""),"",IF(F5>G5,"L",IF(F5<G5,"V","E"))) | J5: SoFi Stadium, Inglewood | K5: Grupo D!D5 | L5: Grupo D!F5 | M5: =AND(ISNUMBER(F5),ISNUMBER(G5)) -> FALSE
A6: B2 | B6: B | C6: 2026-06-13 | D6: 16:00 | E6: Qatar | F6: =IF('Grupo B'!D6="","",'Grupo B'!D6) -> 1 | G6: =IF('Grupo B'!F6="","",'Grupo B'!F6) -> 3 | H6: Suiza | I6: =IF(OR(F6="",G6=""),"",IF(F6>G6,"L",IF(F6<G6,"V","E"))) -> V | J6: Levi's Stadium, Santa Clara | K6: Grupo B!D6 | L6: Grupo B!F6 | M6: =AND(ISNUMBER(F6),ISNUMBER(G6)) -> TRUE
A7: C1 | B7: C | C7: 2026-06-13 | D7: 19:00 | E7: Brasil | F7: =IF('Grupo C'!D5="","",'Grupo C'!D5) | G7: =IF('Grupo C'!F5="","",'Grupo C'!F5) | H7: Marruecos | I7: =IF(OR(F7="",G7=""),"",IF(F7>G7,"L",IF(F7<G7,"V","E"))) | J7: MetLife Stadium, East Rutherford | K7: Grupo C!D5 | L7: Grupo C!F5 | M7: =AND(ISNUMBER(F7),ISNUMBER(G7)) -> FALSE
A8: C2 | B8: C | C8: 2026-06-13 | D8: 22:00 | E8: Haiti | F8: =IF('Grupo C'!D6="","",'Grupo C'!D6) | G8: =IF('Grupo C'!F6="","",'Grupo C'!F6) | H8: Escocia | I8: =IF(OR(F8="",G8=""),"",IF(F8>G8,"L",IF(F8<G8,"V","E"))) | J8: Gillette Stadium, Foxboro | K8: Grupo C!D6 | L8: Grupo C!F6 | M8: =AND(ISNUMBER(F8),ISNUMBER(G8)) -> FALSE
A9: D2 | B9: D | C9: 2026-06-14 | D9: 01:00 | E9: Australia | F9: =IF('Grupo D'!D6="","",'Grupo D'!D6) | G9: =IF('Grupo D'!F6="","",'Grupo D'!F6) | H9: Turquia | I9: =IF(OR(F9="",G9=""),"",IF(F9>G9,"L",IF(F9<G9,"V","E"))) | J9: BC Place, Vancouver | K9: Grupo D!D6 | L9: Grupo D!F6 | M9: =AND(ISNUMBER(F9),ISNUMBER(G9)) -> FALSE
A10: E1 | B10: E | C10: 2026-06-14 | D10: 14:00 | E10: Alemania | F10: =IF('Grupo E'!D5="","",'Grupo E'!D5) | G10: =IF('Grupo E'!F5="","",'Grupo E'!F5) | H10: Curazao | I10: =IF(OR(F10="",G10=""),"",IF(F10>G10,"L",IF(F10<G10,"V","E"))) | J10: NRG Stadium, Houston | K10: Grupo E!D5 | L10: Grupo E!F5 | M10: =AND(ISNUMBER(F10),ISNUMBER(G10)) -> FALSE
A11: F1 | B11: F | C11: 2026-06-14 | D11: 17:00 | E11: Paises Bajos | F11: =IF('Grupo F'!D5="","",'Grupo F'!D5) | G11: =IF('Grupo F'!F5="","",'Grupo F'!F5) | H11: Japon | I11: =IF(OR(F11="",G11=""),"",IF(F11>G11,"L",IF(F11<G11,"V","E"))) | J11: AT&T Stadium, Arlington | K11: Grupo F!D5 | L11: Grupo F!F5 | M11: =AND(ISNUMBER(F11),ISNUMBER(G11)) -> FALSE
A12: E2 | B12: E | C12: 2026-06-14 | D12: 20:00 | E12: Costa de Marfil | F12: =IF('Grupo E'!D6="","",'Grupo E'!D6) | G12: =IF('Grupo E'!F6="","",'Grupo E'!F6) | H12: Ecuador | I12: =IF(OR(F12="",G12=""),"",IF(F12>G12,"L",IF(F12<G12,"V","E"))) | J12: Lincoln Financial Field, Philadelphia | K12: Grupo E!D6 | L12: Grupo E!F6 | M12: =AND(ISNUMBER(F12),ISNUMBER(G12)) -> FALSE
A13: F2 | B13: F | C13: 2026-06-14 | D13: 23:00 | E13: Suecia | F13: =IF('Grupo F'!D6="","",'Grupo F'!D6) | G13: =IF('Grupo F'!F6="","",'Grupo F'!F6) | H13: Tunez | I13: =IF(OR(F13="",G13=""),"",IF(F13>G13,"L",IF(F13<G13,"V","E"))) | J13: Estadio BBVA, Monterrey | K13: Grupo F!D6 | L13: Grupo F!F6 | M13: =AND(ISNUMBER(F13),ISNUMBER(G13)) -> FALSE
A14: H1 | B14: H | C14: 2026-06-15 | D14: 13:00 | E14: España | F14: =IF('Grupo H'!D5="","",'Grupo H'!D5) | G14: =IF('Grupo H'!F5="","",'Grupo H'!F5) | H14: Cabo Verde | I14: =IF(OR(F14="",G14=""),"",IF(F14>G14,"L",IF(F14<G14,"V","E"))) | J14: Mercedes-Benz Stadium, Atlanta | K14: Grupo H!D5 | L14: Grupo H!F5 | M14: =AND(ISNUMBER(F14),ISNUMBER(G14)) -> FALSE
A15: G1 | B15: G | C15: 2026-06-15 | D15: 16:00 | E15: Belgica | F15: =IF('Grupo G'!D5="","",'Grupo G'!D5) | G15: =IF('Grupo G'!F5="","",'Grupo G'!F5) | H15: Egipto | I15: =IF(OR(F15="",G15=""),"",IF(F15>G15,"L",IF(F15<G15,"V","E"))) | J15: Lumen Field, Seattle | K15: Grupo G!D5 | L15: Grupo G!F5 | M15: =AND(ISNUMBER(F15),ISNUMBER(G15)) -> FALSE
A16: H2 | B16: H | C16: 2026-06-15 | D16: 19:00 | E16: Arabia Saudita | F16: =IF('Grupo H'!D6="","",'Grupo H'!D6) | G16: =IF('Grupo H'!F6="","",'Grupo H'!F6) | H16: Uruguay | I16: =IF(OR(F16="",G16=""),"",IF(F16>G16,"L",IF(F16<G16,"V","E"))) | J16: Hard Rock Stadium, Miami | K16: Grupo H!D6 | L16: Grupo H!F6 | M16: =AND(ISNUMBER(F16),ISNUMBER(G16)) -> FALSE
A17: G2 | B17: G | C17: 2026-06-15 | D17: 22:00 | E17: Iran | F17: =IF('Grupo G'!D6="","",'Grupo G'!D6) | G17: =IF('Grupo G'!F6="","",'Grupo G'!F6) | H17: Nueva Zelanda | I17: =IF(OR(F17="",G17=""),"",IF(F17>G17,"L",IF(F17<G17,"V","E"))) | J17: SoFi Stadium, Inglewood | K17: Grupo G!D6 | L17: Grupo G!F6 | M17: =AND(ISNUMBER(F17),ISNUMBER(G17)) -> FALSE
A18: I1 | B18: I | C18: 2026-06-16 | D18: 16:00 | E18: Francia | F18: =IF('Grupo I'!D5="","",'Grupo I'!D5) | G18: =IF('Grupo I'!F5="","",'Grupo I'!F5) | H18: Senegal | I18: =IF(OR(F18="",G18=""),"",IF(F18>G18,"L",IF(F18<G18,"V","E"))) | J18: MetLife Stadium, East Rutherford | K18: Grupo I!D5 | L18: Grupo I!F5 | M18: =AND(ISNUMBER(F18),ISNUMBER(G18)) -> FALSE
A19: I2 | B19: I | C19: 2026-06-16 | D19: 19:00 | E19: Irak | F19: =IF('Grupo I'!D6="","",'Grupo I'!D6) | G19: =IF('Grupo I'!F6="","",'Grupo I'!F6) | H19: Noruega | I19: =IF(OR(F19="",G19=""),"",IF(F19>G19,"L",IF(F19<G19,"V","E"))) | J19: Gillette Stadium, Foxboro | K19: Grupo I!D6 | L19: Grupo I!F6 | M19: =AND(ISNUMBER(F19),ISNUMBER(G19)) -> FALSE
A20: J1 | B20: J | C20: 2026-06-16 | D20: 22:00 | E20: Argentina | F20: =IF('Grupo J'!D5="","",'Grupo J'!D5) | G20: =IF('Grupo J'!F5="","",'Grupo J'!F5) | H20: Argelia | I20: =IF(OR(F20="",G20=""),"",IF(F20>G20,"L",IF(F20<G20,"V","E"))) | J20: Arrowhead Stadium, Kansas City | K20: Grupo J!D5 | L20: Grupo J!F5 | M20: =AND(ISNUMBER(F20),ISNUMBER(G20)) -> FALSE
A21: J2 | B21: J | C21: 2026-06-17 | D21: 01:00 | E21: Austria | F21: =IF('Grupo J'!D6="","",'Grupo J'!D6) | G21: =IF('Grupo J'!F6="","",'Grupo J'!F6) | H21: Jordania | I21: =IF(OR(F21="",G21=""),"",IF(F21>G21,"L",IF(F21<G21,"V","E"))) | J21: Levi's Stadium, Santa Clara | K21: Grupo J!D6 | L21: Grupo J!F6 | M21: =AND(ISNUMBER(F21),ISNUMBER(G21)) -> FALSE
A22: K1 | B22: K | C22: 2026-06-17 | D22: 14:00 | E22: Portugal | F22: =IF('Grupo K'!D5="","",'Grupo K'!D5) | G22: =IF('Grupo K'!F5="","",'Grupo K'!F5) | H22: RD del Congo | I22: =IF(OR(F22="",G22=""),"",IF(F22>G22,"L",IF(F22<G22,"V","E"))) | J22: NRG Stadium, Houston | K22: Grupo K!D5 | L22: Grupo K!F5 | M22: =AND(ISNUMBER(F22),ISNUMBER(G22)) -> FALSE
A23: L1 | B23: L | C23: 2026-06-17 | D23: 17:00 | E23: Inglaterra | F23: =IF('Grupo L'!D5="","",'Grupo L'!D5) | G23: =IF('Grupo L'!F5="","",'Grupo L'!F5) | H23: Croacia | I23: =IF(OR(F23="",G23=""),"",IF(F23>G23,"L",IF(F23<G23,"V","E"))) | J23: AT&T Stadium, Arlington | K23: Grupo L!D5 | L23: Grupo L!F5 | M23: =AND(ISNUMBER(F23),ISNUMBER(G23)) -> FALSE
A24: L2 | B24: L | C24: 2026-06-17 | D24: 20:00 | E24: Ghana | F24: =IF('Grupo L'!D6="","",'Grupo L'!D6) | G24: =IF('Grupo L'!F6="","",'Grupo L'!F6) | H24: Panama | I24: =IF(OR(F24="",G24=""),"",IF(F24>G24,"L",IF(F24<G24,"V","E"))) | J24: BMO Field, Toronto | K24: Grupo L!D6 | L24: Grupo L!F6 | M24: =AND(ISNUMBER(F24),ISNUMBER(G24)) -> FALSE
A25: K2 | B25: K | C25: 2026-06-17 | D25: 23:00 | E25: Uzbekistan | F25: =IF('Grupo K'!D6="","",'Grupo K'!D6) | G25: =IF('Grupo K'!F6="","",'Grupo K'!F6) | H25: Colombia | I25: =IF(OR(F25="",G25=""),"",IF(F25>G25,"L",IF(F25<G25,"V","E"))) | J25: Estadio Azteca, CDMX | K25: Grupo K!D6 | L25: Grupo K!F6 | M25: =AND(ISNUMBER(F25),ISNUMBER(G25)) -> FALSE
A26: A3 | B26: A | C26: 2026-06-18 | D26: 13:00 | E26: Chequia | F26: =IF('Grupo A'!D7="","",'Grupo A'!D7) -> 2 | G26: =IF('Grupo A'!F7="","",'Grupo A'!F7) -> 2 | H26: Sudafrica | I26: =IF(OR(F26="",G26=""),"",IF(F26>G26,"L",IF(F26<G26,"V","E"))) -> E | J26: Mercedes-Benz Stadium, Atlanta | K26: Grupo A!D7 | L26: Grupo A!F7 | M26: =AND(ISNUMBER(F26),ISNUMBER(G26)) -> TRUE
A27: B3 | B27: B | C27: 2026-06-18 | D27: 16:00 | E27: Suiza | F27: =IF('Grupo B'!D7="","",'Grupo B'!D7) | G27: =IF('Grupo B'!F7="","",'Grupo B'!F7) | H27: Bosnia y Herzegovina | I27: =IF(OR(F27="",G27=""),"",IF(F27>G27,"L",IF(F27<G27,"V","E"))) | J27: SoFi Stadium, Inglewood | K27: Grupo B!D7 | L27: Grupo B!F7 | M27: =AND(ISNUMBER(F27),ISNUMBER(G27)) -> FALSE
A28: B4 | B28: B | C28: 2026-06-18 | D28: 19:00 | E28: Canada | F28: =IF('Grupo B'!D8="","",'Grupo B'!D8) | G28: =IF('Grupo B'!F8="","",'Grupo B'!F8) | H28: Qatar | I28: =IF(OR(F28="",G28=""),"",IF(F28>G28,"L",IF(F28<G28,"V","E"))) | J28: BC Place, Vancouver | K28: Grupo B!D8 | L28: Grupo B!F8 | M28: =AND(ISNUMBER(F28),ISNUMBER(G28)) -> FALSE
A29: A4 | B29: A | C29: 2026-06-18 | D29: 22:00 | E29: Mexico | F29: =IF('Grupo A'!D8="","",'Grupo A'!D8) -> 3 | G29: =IF('Grupo A'!F8="","",'Grupo A'!F8) -> 3 | H29: Corea del Sur | I29: =IF(OR(F29="",G29=""),"",IF(F29>G29,"L",IF(F29<G29,"V","E"))) -> E | J29: Estadio Akron, Guadalajara | K29: Grupo A!D8 | L29: Grupo A!F8 | M29: =AND(ISNUMBER(F29),ISNUMBER(G29)) -> TRUE
A30: D3 | B30: D | C30: 2026-06-19 | D30: 16:00 | E30: Estados Unidos | F30: =IF('Grupo D'!D7="","",'Grupo D'!D7) | G30: =IF('Grupo D'!F7="","",'Grupo D'!F7) | H30: Australia | I30: =IF(OR(F30="",G30=""),"",IF(F30>G30,"L",IF(F30<G30,"V","E"))) | J30: Lumen Field, Seattle | K30: Grupo D!D7 | L30: Grupo D!F7 | M30: =AND(ISNUMBER(F30),ISNUMBER(G30)) -> FALSE
A31: C3 | B31: C | C31: 2026-06-19 | D31: 19:00 | E31: Escocia | F31: =IF('Grupo C'!D7="","",'Grupo C'!D7) | G31: =IF('Grupo C'!F7="","",'Grupo C'!F7) | H31: Marruecos | I31: =IF(OR(F31="",G31=""),"",IF(F31>G31,"L",IF(F31<G31,"V","E"))) | J31: Gillette Stadium, Foxboro | K31: Grupo C!D7 | L31: Grupo C!F7 | M31: =AND(ISNUMBER(F31),ISNUMBER(G31)) -> FALSE
A32: C4 | B32: C | C32: 2026-06-19 | D32: 21:30 | E32: Brasil | F32: =IF('Grupo C'!D8="","",'Grupo C'!D8) | G32: =IF('Grupo C'!F8="","",'Grupo C'!F8) | H32: Haiti | I32: =IF(OR(F32="",G32=""),"",IF(F32>G32,"L",IF(F32<G32,"V","E"))) | J32: Lincoln Financial Field, Philadelphia | K32: Grupo C!D8 | L32: Grupo C!F8 | M32: =AND(ISNUMBER(F32),ISNUMBER(G32)) -> FALSE
A33: D4 | B33: D | C33: 2026-06-20 | D33: 00:00 | E33: Turquia | F33: =IF('Grupo D'!D8="","",'Grupo D'!D8) | G33: =IF('Grupo D'!F8="","",'Grupo D'!F8) | H33: Paraguay | I33: =IF(OR(F33="",G33=""),"",IF(F33>G33,"L",IF(F33<G33,"V","E"))) | J33: Levi's Stadium, Santa Clara | K33: Grupo D!D8 | L33: Grupo D!F8 | M33: =AND(ISNUMBER(F33),ISNUMBER(G33)) -> FALSE
A34: F3 | B34: F | C34: 2026-06-20 | D34: 14:00 | E34: Paises Bajos | F34: =IF('Grupo F'!D7="","",'Grupo F'!D7) | G34: =IF('Grupo F'!F7="","",'Grupo F'!F7) | H34: Suecia | I34: =IF(OR(F34="",G34=""),"",IF(F34>G34,"L",IF(F34<G34,"V","E"))) | J34: NRG Stadium, Houston | K34: Grupo F!D7 | L34: Grupo F!F7 | M34: =AND(ISNUMBER(F34),ISNUMBER(G34)) -> FALSE
A35: E3 | B35: E | C35: 2026-06-20 | D35: 17:00 | E35: Alemania | F35: =IF('Grupo E'!D7="","",'Grupo E'!D7) | G35: =IF('Grupo E'!F7="","",'Grupo E'!F7) | H35: Costa de Marfil | I35: =IF(OR(F35="",G35=""),"",IF(F35>G35,"L",IF(F35<G35,"V","E"))) | J35: BMO Field, Toronto | K35: Grupo E!D7 | L35: Grupo E!F7 | M35: =AND(ISNUMBER(F35),ISNUMBER(G35)) -> FALSE
A36: E4 | B36: E | C36: 2026-06-20 | D36: 21:00 | E36: Ecuador | F36: =IF('Grupo E'!D8="","",'Grupo E'!D8) | G36: =IF('Grupo E'!F8="","",'Grupo E'!F8) | H36: Curazao | I36: =IF(OR(F36="",G36=""),"",IF(F36>G36,"L",IF(F36<G36,"V","E"))) | J36: Arrowhead Stadium, Kansas City | K36: Grupo E!D8 | L36: Grupo E!F8 | M36: =AND(ISNUMBER(F36),ISNUMBER(G36)) -> FALSE
A37: F4 | B37: F | C37: 2026-06-21 | D37: 01:00 | E37: Tunez | F37: =IF('Grupo F'!D8="","",'Grupo F'!D8) | G37: =IF('Grupo F'!F8="","",'Grupo F'!F8) | H37: Japon | I37: =IF(OR(F37="",G37=""),"",IF(F37>G37,"L",IF(F37<G37,"V","E"))) | J37: Estadio BBVA, Monterrey | K37: Grupo F!D8 | L37: Grupo F!F8 | M37: =AND(ISNUMBER(F37),ISNUMBER(G37)) -> FALSE
A38: H3 | B38: H | C38: 2026-06-21 | D38: 13:00 | E38: España | F38: =IF('Grupo H'!D7="","",'Grupo H'!D7) | G38: =IF('Grupo H'!F7="","",'Grupo H'!F7) | H38: Arabia Saudita | I38: =IF(OR(F38="",G38=""),"",IF(F38>G38,"L",IF(F38<G38,"V","E"))) | J38: Mercedes-Benz Stadium, Atlanta | K38: Grupo H!D7 | L38: Grupo H!F7 | M38: =AND(ISNUMBER(F38),ISNUMBER(G38)) -> FALSE
A39: G3 | B39: G | C39: 2026-06-21 | D39: 16:00 | E39: Belgica | F39: =IF('Grupo G'!D7="","",'Grupo G'!D7) | G39: =IF('Grupo G'!F7="","",'Grupo G'!F7) | H39: Iran | I39: =IF(OR(F39="",G39=""),"",IF(F39>G39,"L",IF(F39<G39,"V","E"))) | J39: SoFi Stadium, Inglewood | K39: Grupo G!D7 | L39: Grupo G!F7 | M39: =AND(ISNUMBER(F39),ISNUMBER(G39)) -> FALSE
A40: H4 | B40: H | C40: 2026-06-21 | D40: 19:00 | E40: Uruguay | F40: =IF('Grupo H'!D8="","",'Grupo H'!D8) | G40: =IF('Grupo H'!F8="","",'Grupo H'!F8) | H40: Cabo Verde | I40: =IF(OR(F40="",G40=""),"",IF(F40>G40,"L",IF(F40<G40,"V","E"))) | J40: Hard Rock Stadium, Miami | K40: Grupo H!D8 | L40: Grupo H!F8 | M40: =AND(ISNUMBER(F40),ISNUMBER(G40)) -> FALSE
...

Sheet Grupo A
A1: Grupo A
A3: Partidos | B3: (las celdas amarillas son editables)
A4: Fecha | B4: Hora (ARG) | C4: Local | D4: Goles | F4: Goles | G4: Visitante | H4: Resultado | I4: Sede
A5: 2026-06-11 | B5: 16:00 | C5: Mexico | D5: 1 | E5: - | F5: 2 | G5: Sudafrica | H5: =IF(OR(D5="",F5=""),"",IF(D5>F5,"L",IF(D5<F5,"V","E"))) -> V | I5: Estadio Azteca, CDMX
A6: 2026-06-11 | B6: 23:00 | C6: Corea del Sur | D6: 3 | E6: - | F6: 4 | G6: Chequia | H6: =IF(OR(D6="",F6=""),"",IF(D6>F6,"L",IF(D6<F6,"V","E"))) -> V | I6: Estadio Akron, Guadalajara
A7: 2026-06-18 | B7: 13:00 | C7: Chequia | D7: 2 | E7: - | F7: 2 | G7: Sudafrica | H7: =IF(OR(D7="",F7=""),"",IF(D7>F7,"L",IF(D7<F7,"V","E"))) -> E | I7: Mercedes-Benz Stadium, Atlanta
A8: 2026-06-18 | B8: 22:00 | C8: Mexico | D8: 3 | E8: - | F8: 3 | G8: Corea del Sur | H8: =IF(OR(D8="",F8=""),"",IF(D8>F8,"L",IF(D8<F8,"V","E"))) -> E | I8: Estadio Akron, Guadalajara
A9: 2026-06-24 | B9: 22:00 | C9: Chequia | D9: 1 | E9: - | F9: 1 | G9: Mexico | H9: =IF(OR(D9="",F9=""),"",IF(D9>F9,"L",IF(D9<F9,"V","E"))) -> E | I9: Estadio Azteca, CDMX
A10: 2026-06-24 | B10: 22:00 | C10: Sudafrica | D10: 1 | E10: - | F10: 2 | G10: Corea del Sur | H10: =IF(OR(D10="",F10=""),"",IF(D10>F10,"L",IF(D10<F10,"V","E"))) -> V | I10: Estadio BBVA, Monterrey
A11: Tabla (no ordenada)
A12: Equipo | B12: PJ | C12: PG | D12: PE | E12: PP | F12: GF | G12: GC | H12: DG | I12: Pts | K12: Score
A13: Mexico | B13: =SUMPRODUCT((($C$5:$C$10="Mexico")+($G$5:$G$10="Mexico"))*($D$5:$D$10<>"")*($F$5:$F$10<>"")) -> 3 | C13: =SUMPRODUCT(($D$5:$D$10<>"")*($F$5:$F$10<>"")*((($C$5:$C$10="Mexico")*(($D$5:$D$10)>($F$5:$F$10)))+(($G$5:$G$10="Mexico")*(($F$5:$F$10)>($D$5:$D$10))))) -> 0 | D13: =SUMPRODUCT(($D$5:$D$10<>"")*($F$5:$F$10<>"")*(($C$5:$C$10="Mexico")+($G$5:$G$10="Mexico"))*(($D$5:$D$10)=($F$5:$F$10))) -> 2 | E13: =SUMPRODUCT(($D$5:$D$10<>"")*($F$5:$F$10<>"")*((($C$5:$C$10="Mexico")*(($D$5:$D$10)<($F$5:$F$10)))+(($G$5:$G$10="Mexico")*(($F$5:$F$10)<($D$5:$D$10))))) -> 1 | F13: =SUMPRODUCT(($D$5:$D$10<>"")*($F$5:$F$10<>"")*((($C$5:$C$10="Mexico")*($D$5:$D$10))+(($G$5:$G$10="Mexico")*($F$5:$F$10)))) -> 5 | G13: =SUMPRODUCT(($D$5:$D$10<>"")*($F$5:$F$10<>"")*((($C$5:$C$10="Mexico")*($F$5:$F$10))+(($G$5:$G$10="Mexico")*($D$5:$D$10)))) -> 6 | H13: =F13-G13 -> -1 | I13: =C13*3+D13 -> 2 | K13: =I13*1000000000+H13*1000000+F13*1000+(4) -> 1999005004
A14: Sudafrica | B14: =SUMPRODUCT((($C$5:$C$10="Sudafrica")+($G$5:$G$10="Sudafrica"))*($D$5:$D$10<>"")*($F$5:$F$10<>"")) -> 3 | C14: =SUMPRODUCT(($D$5:$D$10<>"")*($F$5:$F$10<>"")*((($C$5:$C$10="Sudafrica")*(($D$5:$D$10)>($F$5:$F$10)))+(($G$5:$G$10="Sudafrica")*(($F$5:$F$10)>($D$5:$D$10))))) -> 1 | D14: =SUMPRODUCT(($D$5:$D$10<>"")*($F$5:$F$10<>"")*(($C$5:$C$10="Sudafrica")+($G$5:$G$10="Sudafrica"))*(($D$5:$D$10)=($F$5:$F$10))) -> 1 | E14: =SUMPRODUCT(($D$5:$D$10<>"")*($F$5:$F$10<>"")*((($C$5:$C$10="Sudafrica")*(($D$5:$D$10)<($F$5:$F$10)))+(($G$5:$G$10="Sudafrica")*(($F$5:$F$10)<($D$5:$D$10))))) -> 1 | F14: =SUMPRODUCT(($D$5:$D$10<>"")*($F$5:$F$10<>"")*((($C$5:$C$10="Sudafrica")*($D$5:$D$10))+(($G$5:$G$10="Sudafrica")*($F$5:$F$10)))) -> 5 | G14: =SUMPRODUCT(($D$5:$D$10<>"")*($F$5:$F$10<>"")*((($C$5:$C$10="Sudafrica")*($F$5:$F$10))+(($G$5:$G$10="Sudafrica")*($D$5:$D$10)))) -> 5 | H14: =F14-G14 -> 0 | I14: =C14*3+D14 -> 4 | K14: =I14*1000000000+H14*1000000+F14*1000+(3) -> 4000005003
A15: Corea del Sur | B15: =SUMPRODUCT((($C$5:$C$10="Corea del Sur")+($G$5:$G$10="Corea del Sur"))*($D$5:$D$10<>"")*($F$5:$F$10<>"")) -> 3 | C15: =SUMPRODUCT(($D$5:$D$10<>"")*($F$5:$F$10<>"")*((($C$5:$C$10="Corea del Sur")*(($D$5:$D$10)>($F$5:$F$10)))+(($G$5:$G$10="Corea del Sur")*(($F$5:$F$10)>($D$5:$D$10))))) -> 1 | D15: =SUMPRODUCT(($D$5:$D$10<>"")*($F$5:$F$10<>"")*(($C$5:$C$10="Corea del Sur")+($G$5:$G$10="Corea del Sur"))*(($D$5:$D$10)=($F$5:$F$10))) -> 1 | E15: =SUMPRODUCT(($D$5:$D$10<>"")*($F$5:$F$10<>"")*((($C$5:$C$10="Corea del Sur")*(($D$5:$D$10)<($F$5:$F$10)))+(($G$5:$G$10="Corea del Sur")*(($F$5:$F$10)<($D$5:$D$10))))) -> 1 | F15: =SUMPRODUCT(($D$5:$D$10<>"")*($F$5:$F$10<>"")*((($C$5:$C$10="Corea del Sur")*($D$5:$D$10))+(($G$5:$G$10="Corea del Sur")*($F$5:$F$10)))) -> 8 | G15: =SUMPRODUCT(($D$5:$D$10<>"")*($F$5:$F$10<>"")*((($C$5:$C$10="Corea del Sur")*($F$5:$F$10))+(($G$5:$G$10="Corea del Sur")*($D$5:$D$10)))) -> 8 | H15: =F15-G15 -> 0 | I15: =C15*3+D15 -> 4 | K15: =I15*1000000000+H15*1000000+F15*1000+(2) -> 4000008002
A16: Chequia | B16: =SUMPRODUCT((($C$5:$C$10="Chequia")+($G$5:$G$10="Chequia"))*($D$5:$D$10<>"")*($F$5:$F$10<>"")) -> 3 | C16: =SUMPRODUCT(($D$5:$D$10<>"")*($F$5:$F$10<>"")*((($C$5:$C$10="Chequia")*(($D$5:$D$10)>($F$5:$F$10)))+(($G$5:$G$10="Chequia")*(($F$5:$F$10)>($D$5:$D$10))))) -> 1 | D16: =SUMPRODUCT(($D$5:$D$10<>"")*($F$5:$F$10<>"")*(($C$5:$C$10="Chequia")+($G$5:$G$10="Chequia"))*(($D$5:$D$10)=($F$5:$F$10))) -> 2 | E16: =SUMPRODUCT(($D$5:$D$10<>"")*($F$5:$F$10<>"")*((($C$5:$C$10="Chequia")*(($D$5:$D$10)<($F$5:$F$10)))+(($G$5:$G$10="Chequia")*(($F$5:$F$10)<($D$5:$D$10))))) -> 0 | F16: =SUMPRODUCT(($D$5:$D$10<>"")*($F$5:$F$10<>"")*((($C$5:$C$10="Chequia")*($D$5:$D$10))+(($G$5:$G$10="Chequia")*($F$5:$F$10)))) -> 7 | G16: =SUMPRODUCT(($D$5:$D$10<>"")*($F$5:$F$10<>"")*((($C$5:$C$10="Chequia")*($F$5:$F$10))+(($G$5:$G$10="Chequia")*($D$5:$D$10)))) -> 6 | H16: =F16-G16 -> 1 | I16: =C16*3+D16 -> 5 | K16: =I16*1000000000+H16*1000000+F16*1000+(1) -> 5001007001
A17: Tabla de posiciones (en vivo)
A18: # | B18: Equipo | C18: PJ | D18: PG | E18: PE | F18: PP | G18: GF | H18: GC | I18: DG | J18: Pts | K18: Estado
A19: 1 | B19: =INDEX($A$13:$A$16,MATCH(LARGE($K$13:$K$16,1),$K$13:$K$16,0)) -> Chequia | C19: =INDEX($B$13:$I$16,MATCH(LARGE($K$13:$K$16,1),$K$13:$K$16,0),1) -> 3 | D19: =INDEX($B$13:$I$16,MATCH(LARGE($K$13:$K$16,1),$K$13:$K$16,0),2) -> 1 | E19: =INDEX($B$13:$I$16,MATCH(LARGE($K$13:$K$16,1),$K$13:$K$16,0),3) -> 2 | F19: =INDEX($B$13:$I$16,MATCH(LARGE($K$13:$K$16,1),$K$13:$K$16,0),4) -> 0 | G19: =INDEX($B$13:$I$16,MATCH(LARGE($K$13:$K$16,1),$K$13:$K$16,0),5) -> 7 | H19: =INDEX($B$13:$I$16,MATCH(LARGE($K$13:$K$16,1),$K$13:$K$16,0),6) -> 6 | I19: =INDEX($B$13:$I$16,MATCH(LARGE($K$13:$K$16,1),$K$13:$K$16,0),7) -> 1 | J19: =INDEX($B$13:$I$16,MATCH(LARGE($K$13:$K$16,1),$K$13:$K$16,0),8) -> 5 | K19: ="Clasificado 1ro" -> Clasificado 1ro
A20: 2 | B20: =INDEX($A$13:$A$16,MATCH(LARGE($K$13:$K$16,2),$K$13:$K$16,0)) -> Corea del Sur | C20: =INDEX($B$13:$I$16,MATCH(LARGE($K$13:$K$16,2),$K$13:$K$16,0),1) -> 3 | D20: =INDEX($B$13:$I$16,MATCH(LARGE($K$13:$K$16,2),$K$13:$K$16,0),2) -> 1 | E20: =INDEX($B$13:$I$16,MATCH(LARGE($K$13:$K$16,2),$K$13:$K$16,0),3) -> 1 | F20: =INDEX($B$13:$I$16,MATCH(LARGE($K$13:$K$16,2),$K$13:$K$16,0),4) -> 1 | G20: =INDEX($B$13:$I$16,MATCH(LARGE($K$13:$K$16,2),$K$13:$K$16,0),5) -> 8 | H20: =INDEX($B$13:$I$16,MATCH(LARGE($K$13:$K$16,2),$K$13:$K$16,0),6) -> 8 | I20: =INDEX($B$13:$I$16,MATCH(LARGE($K$13:$K$16,2),$K$13:$K$16,0),7) -> 0 | J20: =INDEX($B$13:$I$16,MATCH(LARGE($K$13:$K$16,2),$K$13:$K$16,0),8) -> 4 | K20: ="Clasificado 2do" -> Clasificado 2do
A21: 3 | B21: =INDEX($A$13:$A$16,MATCH(LARGE($K$13:$K$16,3),$K$13:$K$16,0)) -> Sudafrica | C21: =INDEX($B$13:$I$16,MATCH(LARGE($K$13:$K$16,3),$K$13:$K$16,0),1) -> 3 | D21: =INDEX($B$13:$I$16,MATCH(LARGE($K$13:$K$16,3),$K$13:$K$16,0),2) -> 1 | E21: =INDEX($B$13:$I$16,MATCH(LARGE($K$13:$K$16,3),$K$13:$K$16,0),3) -> 1 | F21: =INDEX($B$13:$I$16,MATCH(LARGE($K$13:$K$16,3),$K$13:$K$16,0),4) -> 1 | G21: =INDEX($B$13:$I$16,MATCH(LARGE($K$13:$K$16,3),$K$13:$K$16,0),5) -> 5 | H21: =INDEX($B$13:$I$16,MATCH(LARGE($K$13:$K$16,3),$K$13:$K$16,0),6) -> 5 | I21: =INDEX($B$13:$I$16,MATCH(LARGE($K$13:$K$16,3),$K$13:$K$16,0),7) -> 0 | J21: =INDEX($B$13:$I$16,MATCH(LARGE($K$13:$K$16,3),$K$13:$K$16,0),8) -> 4 | K21: ="3ro (puede avanzar)" -> 3ro (puede avanzar)
A22: 4 | B22: =INDEX($A$13:$A$16,MATCH(LARGE($K$13:$K$16,4),$K$13:$K$16,0)) -> Mexico | C22: =INDEX($B$13:$I$16,MATCH(LARGE($K$13:$K$16,4),$K$13:$K$16,0),1) -> 3 | D22: =INDEX($B$13:$I$16,MATCH(LARGE($K$13:$K$16,4),$K$13:$K$16,0),2) -> 0 | E22: =INDEX($B$13:$I$16,MATCH(LARGE($K$13:$K$16,4),$K$13:$K$16,0),3) -> 2 | F22: =INDEX($B$13:$I$16,MATCH(LARGE($K$13:$K$16,4),$K$13:$K$16,0),4) -> 1 | G22: =INDEX($B$13:$I$16,MATCH(LARGE($K$13:$K$16,4),$K$13:$K$16,0),5) -> 5 | H22: =INDEX($B$13:$I$16,MATCH(LARGE($K$13:$K$16,4),$K$13:$K$16,0),6) -> 6 | I22: =INDEX($B$13:$I$16,MATCH(LARGE($K$13:$K$16,4),$K$13:$K$16,0),7) -> -1 | J22: =INDEX($B$13:$I$16,MATCH(LARGE($K$13:$K$16,4),$K$13:$K$16,0),8) -> 2 | K22: ="Eliminado" -> Eliminado

Sheet Grupo B
A1: Grupo B
A3: Partidos | B3: (las celdas amarillas son editables)
A4: Fecha | B4: Hora (ARG) | C4: Local | D4: Goles | F4: Goles | G4: Visitante | H4: Resultado | I4: Sede
A5: 2026-06-12 | B5: 16:00 | C5: Canada | D5: 1 | E5: - | F5: 2 | G5: Bosnia y Herzegovina | H5: =IF(OR(D5="",F5=""),"",IF(D5>F5,"L",IF(D5<F5,"V","E"))) -> V | I5: BMO Field, Toronto
A6: 2026-06-13 | B6: 16:00 | C6: Qatar | D6: 1 | E6: - | F6: 3 | G6: Suiza | H6: =IF(OR(D6="",F6=""),"",IF(D6>F6,"L",IF(D6<F6,"V","E"))) -> V | I6: Levi's Stadium, Santa Clara
A7: 2026-06-18 | B7: 16:00 | C7: Suiza | E7: - | G7: Bosnia y Herzegovina | H7: =IF(OR(D7="",F7=""),"",IF(D7>F7,"L",IF(D7<F7,"V","E"))) | I7: SoFi Stadium, Inglewood
A8: 2026-06-18 | B8: 19:00 | C8: Canada | E8: - | G8: Qatar | H8: =IF(OR(D8="",F8=""),"",IF(D8>F8,"L",IF(D8<F8,"V","E"))) | I8: BC Place, Vancouver
A9: 2026-06-24 | B9: 16:00 | C9: Suiza | E9: - | G9: Canada | H9: =IF(OR(D9="",F9=""),"",IF(D9>F9,"L",IF(D9<F9,"V","E"))) | I9: BC Place, Vancouver
A10: 2026-06-24 | B10: 16:00 | C10: Bosnia y Herzegovina | E10: - | G10: Qatar | H10: =IF(OR(D10="",F10=""),"",IF(D10>F10,"L",IF(D10<F10,"V","E"))) | I10: Lumen Field, Seattle
A11: Tabla (no ordenada)
A12: Equipo | B12: PJ | C12: PG | D12: PE | E12: PP | F12: GF | G12: GC | H12: DG | I12: Pts | K12: Score
A13: Canada | B13: =SUMPRODUCT((($C$5:$C$10="Canada")+($G$5:$G$10="Canada"))*($D$5:$D$10<>"")*($F$5:$F$10<>"")) -> 1 | C13: =SUMPRODUCT(($D$5:$D$10<>"")*($F$5:$F$10<>"")*((($C$5:$C$10="Canada")*(($D$5:$D$10)>($F$5:$F$10)))+(($G$5:$G$10="Canada")*(($F$5:$F$10)>($D$5:$D$10))))) -> 0 | D13: =SUMPRODUCT(($D$5:$D$10<>"")*($F$5:$F$10<>"")*(($C$5:$C$10="Canada")+($G$5:$G$10="Canada"))*(($D$5:$D$10)=($F$5:$F$10))) -> 0 | E13: =SUMPRODUCT(($D$5:$D$10<>"")*($F$5:$F$10<>"")*((($C$5:$C$10="Canada")*(($D$5:$D$10)<($F$5:$F$10)))+(($G$5:$G$10="Canada")*(($F$5:$F$10)<($D$5:$D$10))))) -> 1 | F13: =SUMPRODUCT(($D$5:$D$10<>"")*($F$5:$F$10<>"")*((($C$5:$C$10="Canada")*($D$5:$D$10))+(($G$5:$G$10="Canada")*($F$5:$F$10)))) -> 1 | G13: =SUMPRODUCT(($D$5:$D$10<>"")*($F$5:$F$10<>"")*((($C$5:$C$10="Canada")*($F$5:$F$10))+(($G$5:$G$10="Canada")*($D$5:$D$10)))) -> 2 | H13: =F13-G13 -> -1 | I13: =C13*3+D13 -> 0 | K13: =I13*1000000000+H13*1000000+F13*1000+(4) -> -998996
A14: Bosnia y Herzegovina | B14: =SUMPRODUCT((($C$5:$C$10="Bosnia y Herzegovina")+($G$5:$G$10="Bosnia y Herzegovina"))*($D$5:$D$10<>"")*($F$5:$F$10<>"")) -> 1 | C14: =SUMPRODUCT(($D$5:$D$10<>"")*($F$5:$F$10<>"")*((($C$5:$C$10="Bosnia y Herzegovina")*(($D$5:$D$10)>($F$5:$F$10)))+(($G$5:$G$10="Bosnia y Herzegovina")*(($F$5:$F$10)>($D$5:$D$10))))) -> 1 | D14: =SUMPRODUCT(($D$5:$D$10<>"")*($F$5:$F$10<>"")*(($C$5:$C$10="Bosnia y Herzegovina")+($G$5:$G$10="Bosnia y Herzegovina"))*(($D$5:$D$10)=($F$5:$F$10))) -> 0 | E14: =SUMPRODUCT(($D$5:$D$10<>"")*($F$5:$F$10<>"")*((($C$5:$C$10="Bosnia y Herzegovina")*(($D$5:$D$10)<($F$5:$F$10)))+(($G$5:$G$10="Bosnia y Herzegovina")*(($F$5:$F$10)<($D$5:$D$10))))) -> 0 | F14: =SUMPRODUCT(($D$5:$D$10<>"")*($F$5:$F$10<>"")*((($C$5:$C$10="Bosnia y Herzegovina")*($D$5:$D$10))+(($G$5:$G$10="Bosnia y Herzegovina")*($F$5:$F$10)))) -> 2 | G14: =SUMPRODUCT(($D$5:$D$10<>"")*($F$5:$F$10<>"")*((($C$5:$C$10="Bosnia y Herzegovina")*($F$5:$F$10))+(($G$5:$G$10="Bosnia y Herzegovina")*($D$5:$D$10)))) -> 1 | H14: =F14-G14 -> 1 | I14: =C14*3+D14 -> 3 | K14: =I14*1000000000+H14*1000000+F14*1000+(3) -> 3001002003
A15: Qatar | B15: =SUMPRODUCT((($C$5:$C$10="Qatar")+($G$5:$G$10="Qatar"))*($D$5:$D$10<>"")*($F$5:$F$10<>"")) -> 1 | C15: =SUMPRODUCT(($D$5:$D$10<>"")*($F$5:$F$10<>"")*((($C$5:$C$10="Qatar")*(($D$5:$D$10)>($F$5:$F$10)))+(($G$5:$G$10="Qatar")*(($F$5:$F$10)>($D$5:$D$10))))) -> 0 | D15: =SUMPRODUCT(($D$5:$D$10<>"")*($F$5:$F$10<>"")*(($C$5:$C$10="Qatar")+($G$5:$G$10="Qatar"))*(($D$5:$D$10)=($F$5:$F$10))) -> 0 | E15: =SUMPRODUCT(($D$5:$D$10<>"")*($F$5:$F$10<>"")*((($C$5:$C$10="Qatar")*(($D$5:$D$10)<($F$5:$F$10)))+(($G$5:$G$10="Qatar")*(($F$5:$F$10)<($D$5:$D$10))))) -> 1 | F15: =SUMPRODUCT(($D$5:$D$10<>"")*($F$5:$F$10<>"")*((($C$5:$C$10="Qatar")*($D$5:$D$10))+(($G$5:$G$10="Qatar")*($F$5:$F$10)))) -> 1 | G15: =SUMPRODUCT(($D$5:$D$10<>"")*($F$5:$F$10<>"")*((($C$5:$C$10="Qatar")*($F$5:$F$10))+(($G$5:$G$10="Qatar")*($D$5:$D$10)))) -> 3 | H15: =F15-G15 -> -2 | I15: =C15*3+D15 -> 0 | K15: =I15*1000000000+H15*1000000+F15*1000+(2) -> -1998998
A16: Suiza | B16: =SUMPRODUCT((($C$5:$C$10="Suiza")+($G$5:$G$10="Suiza"))*($D$5:$D$10<>"")*($F$5:$F$10<>"")) -> 1 | C16: =SUMPRODUCT(($D$5:$D$10<>"")*($F$5:$F$10<>"")*((($C$5:$C$10="Suiza")*(($D$5:$D$10)>($F$5:$F$10)))+(($G$5:$G$10="Suiza")*(($F$5:$F$10)>($D$5:$D$10))))) -> 1 | D16: =SUMPRODUCT(($D$5:$D$10<>"")*($F$5:$F$10<>"")*(($C$5:$C$10="Suiza")+($G$5:$G$10="Suiza"))*(($D$5:$D$10)=($F$5:$F$10))) -> 0 | E16: =SUMPRODUCT(($D$5:$D$10<>"")*($F$5:$F$10<>"")*((($C$5:$C$10="Suiza")*(($D$5:$D$10)<($F$5:$F$10)))+(($G$5:$G$10="Suiza")*(($F$5:$F$10)<($D$5:$D$10))))) -> 0 | F16: =SUMPRODUCT(($D$5:$D$10<>"")*($F$5:$F$10<>"")*((($C$5:$C$10="Suiza")*($D$5:$D$10))+(($G$5:$G$10="Suiza")*($F$5:$F$10)))) -> 3 | G16: =SUMPRODUCT(($D$5:$D$10<>"")*($F$5:$F$10<>"")*((($C$5:$C$10="Suiza")*($F$5:$F$10))+(($G$5:$G$10="Suiza")*($D$5:$D$10)))) -> 1 | H16: =F16-G16 -> 2 | I16: =C16*3+D16 -> 3 | K16: =I16*1000000000+H16*1000000+F16*1000+(1) -> 3002003001
A17: Tabla de posiciones (en vivo)
A18: # | B18: Equipo | C18: PJ | D18: PG | E18: PE | F18: PP | G18: GF | H18: GC | I18: DG | J18: Pts | K18: Estado
A19: 1 | B19: =INDEX($A$13:$A$16,MATCH(LARGE($K$13:$K$16,1),$K$13:$K$16,0)) -> Suiza | C19: =INDEX($B$13:$I$16,MATCH(LARGE($K$13:$K$16,1),$K$13:$K$16,0),1) -> 1 | D19: =INDEX($B$13:$I$16,MATCH(LARGE($K$13:$K$16,1),$K$13:$K$16,0),2) -> 1 | E19: =INDEX($B$13:$I$16,MATCH(LARGE($K$13:$K$16,1),$K$13:$K$16,0),3) -> 0 | F19: =INDEX($B$13:$I$16,MATCH(LARGE($K$13:$K$16,1),$K$13:$K$16,0),4) -> 0 | G19: =INDEX($B$13:$I$16,MATCH(LARGE($K$13:$K$16,1),$K$13:$K$16,0),5) -> 3 | H19: =INDEX($B$13:$I$16,MATCH(LARGE($K$13:$K$16,1),$K$13:$K$16,0),6) -> 1 | I19: =INDEX($B$13:$I$16,MATCH(LARGE($K$13:$K$16,1),$K$13:$K$16,0),7) -> 2 | J19: =INDEX($B$13:$I$16,MATCH(LARGE($K$13:$K$16,1),$K$13:$K$16,0),8) -> 3 | K19: ="Clasificado 1ro" -> Clasificado 1ro
A20: 2 | B20: =INDEX($A$13:$A$16,MATCH(LARGE($K$13:$K$16,2),$K$13:$K$16,0)) -> Bosnia y Herzegovina | C20: =INDEX($B$13:$I$16,MATCH(LARGE($K$13:$K$16,2),$K$13:$K$16,0),1) -> 1 | D20: =INDEX($B$13:$I$16,MATCH(LARGE($K$13:$K$16,2),$K$13:$K$16,0),2) -> 1 | E20: =INDEX($B$13:$I$16,MATCH(LARGE($K$13:$K$16,2),$K$13:$K$16,0),3) -> 0 | F20: =INDEX($B$13:$I$16,MATCH(LARGE($K$13:$K$16,2),$K$13:$K$16,0),4) -> 0 | G20: =INDEX($B$13:$I$16,MATCH(LARGE($K$13:$K$16,2),$K$13:$K$16,0),5) -> 2 | H20: =INDEX($B$13:$I$16,MATCH(LARGE($K$13:$K$16,2),$K$13:$K$16,0),6) -> 1 | I20: =INDEX($B$13:$I$16,MATCH(LARGE($K$13:$K$16,2),$K$13:$K$16,0),7) -> 1 | J20: =INDEX($B$13:$I$16,MATCH(LARGE($K$13:$K$16,2),$K$13:$K$16,0),8) -> 3 | K20: ="Clasificado 2do" -> Clasificado 2do
A21: 3 | B21: =INDEX($A$13:$A$16,MATCH(LARGE($K$13:$K$16,3),$K$13:$K$16,0)) -> Canada | C21: =INDEX($B$13:$I$16,MATCH(LARGE($K$13:$K$16,3),$K$13:$K$16,0),1) -> 1 | D21: =INDEX($B$13:$I$16,MATCH(LARGE($K$13:$K$16,3),$K$13:$K$16,0),2) -> 0 | E21: =INDEX($B$13:$I$16,MATCH(LARGE($K$13:$K$16,3),$K$13:$K$16,0),3) -> 0 | F21: =INDEX($B$13:$I$16,MATCH(LARGE($K$13:$K$16,3),$K$13:$K$16,0),4) -> 1 | G21: =INDEX($B$13:$I$16,MATCH(LARGE($K$13:$K$16,3),$K$13:$K$16,0),5) -> 1 | H21: =INDEX($B$13:$I$16,MATCH(LARGE($K$13:$K$16,3),$K$13:$K$16,0),6) -> 2 | I21: =INDEX($B$13:$I$16,MATCH(LARGE($K$13:$K$16,3),$K$13:$K$16,0),7) -> -1 | J21: =INDEX($B$13:$I$16,MATCH(LARGE($K$13:$K$16,3),$K$13:$K$16,0),8) -> 0 | K21: ="3ro (puede avanzar)" -> 3ro (puede avanzar)
A22: 4 | B22: =INDEX($A$13:$A$16,MATCH(LARGE($K$13:$K$16,4),$K$13:$K$16,0)) -> Qatar | C22: =INDEX($B$13:$I$16,MATCH(LARGE($K$13:$K$16,4),$K$13:$K$16,0),1) -> 1 | D22: =INDEX($B$13:$I$16,MATCH(LARGE($K$13:$K$16,4),$K$13:$K$16,0),2) -> 0 | E22: =INDEX($B$13:$I$16,MATCH(LARGE($K$13:$K$16,4),$K$13:$K$16,0),3) -> 0 | F22: =INDEX($B$13:$I$16,MATCH(LARGE($K$13:$K$16,4),$K$13:$K$16,0),4) -> 1 | G22: =INDEX($B$13:$I$16,MATCH(LARGE($K$13:$K$16,4),$K$13:$K$16,0),5) -> 1 | H22: =INDEX($B$13:$I$16,MATCH(LARGE($K$13:$K$16,4),$K$13:$K$16,0),6) -> 3 | I22: =INDEX($B$13:$I$16,MATCH(LARGE($K$13:$K$16,4),$K$13:$K$16,0),7) -> -2 | J22: =INDEX($B$13:$I$16,MATCH(LARGE($K$13:$K$16,4),$K$13:$K$16,0),8) -> 0 | K22: ="Eliminado" -> Eliminado

Sheet Grupo C
A1: Grupo C
A3: Partidos | B3: (las celdas amarillas son editables)
A4: Fecha | B4: Hora (ARG) | C4: Local | D4: Goles | F4: Goles | G4: Visitante | H4: Resultado | I4: Sede
A5: 2026-06-13 | B5: 19:00 | C5: Brasil | E5: - | G5: Marruecos | H5: =IF(OR(D5="",F5=""),"",IF(D5>F5,"L",IF(D5<F5,"V","E"))) | I5: MetLife Stadium, East Rutherford
A6: 2026-06-13 | B6: 22:00 | C6: Haiti | E6: - | G6: Escocia | H6: =IF(OR(D6="",F6=""),"",IF(D6>F6,"L",IF(D6<F6,"V","E"))) | I6: Gillette Stadium, Foxboro
A7: 2026-06-19 | B7: 19:00 | C7: Escocia | E7: - | G7: Marruecos | H7: =IF(OR(D7="",F7=""),"",IF(D7>F7,"L",IF(D7<F7,"V","E"))) | I7: Gillette Stadium, Foxboro
A8: 2026-06-19 | B8: 21:30 | C8: Brasil | E8: - | G8: Haiti | H8: =IF(OR(D8="",F8=""),"",IF(D8>F8,"L",IF(D8<F8,"V","E"))) | I8: Lincoln Financial Field, Philadelphia
A9: 2026-06-24 | B9: 19:00 | C9: Escocia | E9: - | G9: Brasil | H9: =IF(OR(D9="",F9=""),"",IF(D9>F9,"L",IF(D9<F9,"V","E"))) | I9: Hard Rock Stadium, Miami
A10: 2026-06-24 | B10: 19:00 | C10: Marruecos | E10: - | G10: Haiti | H10: =IF(OR(D10="",F10=""),"",IF(D10>F10,"L",IF(D10<F10,"V","E"))) | I10: Mercedes-Benz Stadium, Atlanta
A11: Tabla (no ordenada)
A12: Equipo | B12: PJ | C12: PG | D12: PE | E12: PP | F12: GF | G12: GC | H12: DG | I12: Pts | K12: Score
A13: Brasil | B13: =SUMPRODUCT((($C$5:$C$10="Brasil")+($G$5:$G$10="Brasil"))*($D$5:$D$10<>"")*($F$5:$F$10<>"")) -> 0 | C13: =SUMPRODUCT(($D$5:$D$10<>"")*($F$5:$F$10<>"")*((($C$5:$C$10="Brasil")*(($D$5:$D$10)>($F$5:$F$10)))+(($G$5:$G$10="Brasil")*(($F$5:$F$10)>($D$5:$D$10))))) -> 0 | D13: =SUMPRODUCT(($D$5:$D$10<>"")*($F$5:$F$10<>"")*(($C$5:$C$10="Brasil")+($G$5:$G$10="Brasil"))*(($D$5:$D$10)=($F$5:$F$10))) -> 0 | E13: =SUMPRODUCT(($D$5:$D$10<>"")*($F$5:$F$10<>"")*((($C$5:$C$10="Brasil")*(($D$5:$D$10)<($F$5:$F$10)))+(($G$5:$G$10="Brasil")*(($F$5:$F$10)<($D$5:$D$10))))) -> 0 | F13: =SUMPRODUCT(($D$5:$D$10<>"")*($F$5:$F$10<>"")*((($C$5:$C$10="Brasil")*($D$5:$D$10))+(($G$5:$G$10="Brasil")*($F$5:$F$10)))) -> 0 | G13: =SUMPRODUCT(($D$5:$D$10<>"")*($F$5:$F$10<>"")*((($C$5:$C$10="Brasil")*($F$5:$F$10))+(($G$5:$G$10="Brasil")*($D$5:$D$10)))) -> 0 | H13: =F13-G13 -> 0 | I13: =C13*3+D13 -> 0 | K13: =I13*1000000000+H13*1000000+F13*1000+(4) -> 4
A14: Marruecos | B14: =SUMPRODUCT((($C$5:$C$10="Marruecos")+($G$5:$G$10="Marruecos"))*($D$5:$D$10<>"")*($F$5:$F$10<>"")) -> 0 | C14: =SUMPRODUCT(($D$5:$D$10<>"")*($F$5:$F$10<>"")*((($C$5:$C$10="Marruecos")*(($D$5:$D$10)>($F$5:$F$10)))+(($G$5:$G$10="Marruecos")*(($F$5:$F$10)>($D$5:$D$10))))) -> 0 | D14: =SUMPRODUCT(($D$5:$D$10<>"")*($F$5:$F$10<>"")*(($C$5:$C$10="Marruecos")+($G$5:$G$10="Marruecos"))*(($D$5:$D$10)=($F$5:$F$10))) -> 0 | E14: =SUMPRODUCT(($D$5:$D$10<>"")*($F$5:$F$10<>"")*((($C$5:$C$10="Marruecos")*(($D$5:$D$10)<($F$5:$F$10)))+(($G$5:$G$10="Marruecos")*(($F$5:$F$10)<($D$5:$D$10))))) -> 0 | F14: =SUMPRODUCT(($D$5:$D$10<>"")*($F$5:$F$10<>"")*((($C$5:$C$10="Marruecos")*($D$5:$D$10))+(($G$5:$G$10="Marruecos")*($F$5:$F$10)))) -> 0 | G14: =SUMPRODUCT(($D$5:$D$10<>"")*($F$5:$F$10<>"")*((($C$5:$C$10="Marruecos")*($F$5:$F$10))+(($G$5:$G$10="Marruecos")*($D$5:$D$10)))) -> 0 | H14: =F14-G14 -> 0 | I14: =C14*3+D14 -> 0 | K14: =I14*1000000000+H14*1000000+F14*1000+(3) -> 3
A15: Haiti | B15: =SUMPRODUCT((($C$5:$C$10="Haiti")+($G$5:$G$10="Haiti"))*($D$5:$D$10<>"")*($F$5:$F$10<>"")) -> 0 | C15: =SUMPRODUCT(($D$5:$D$10<>"")*($F$5:$F$10<>"")*((($C$5:$C$10="Haiti")*(($D$5:$D$10)>($F$5:$F$10)))+(($G$5:$G$10="Haiti")*(($F$5:$F$10)>($D$5:$D$10))))) -> 0 | D15: =SUMPRODUCT(($D$5:$D$10<>"")*($F$5:$F$10<>"")*(($C$5:$C$10="Haiti")+($G$5:$G$10="Haiti"))*(($D$5:$D$10)=($F$5:$F$10))) -> 0 | E15: =SUMPRODUCT(($D$5:$D$10<>"")*($F$5:$F$10<>"")*((($C$5:$C$10="Haiti")*(($D$5:$D$10)<($F$5:$F$10)))+(($G$5:$G$10="Haiti")*(($F$5:$F$10)<($D$5:$D$10))))) -> 0 | F15: =SUMPRODUCT(($D$5:$D$10<>"")*($F$5:$F$10<>"")*((($C$5:$C$10="Haiti")*($D$5:$D$10))+(($G$5:$G$10="Haiti")*($F$5:$F$10)))) -> 0 | G15: =SUMPRODUCT(($D$5:$D$10<>"")*($F$5:$F$10<>"")*((($C$5:$C$10="Haiti")*($F$5:$F$10))+(($G$5:$G$10="Haiti")*($D$5:$D$10)))) -> 0 | H15: =F15-G15 -> 0 | I15: =C15*3+D15 -> 0 | K15: =I15*1000000000+H15*1000000+F15*1000+(2) -> 2
A16: Escocia | B16: =SUMPRODUCT((($C$5:$C$10="Escocia")+($G$5:$G$10="Escocia"))*($D$5:$D$10<>"")*($F$5:$F$10<>"")) -> 0 | C16: =SUMPRODUCT(($D$5:$D$10<>"")*($F$5:$F$10<>"")*((($C$5:$C$10="Escocia")*(($D$5:$D$10)>($F$5:$F$10)))+(($G$5:$G$10="Escocia")*(($F$5:$F$10)>($D$5:$D$10))))) -> 0 | D16: =SUMPRODUCT(($D$5:$D$10<>"")*($F$5:$F$10<>"")*(($C$5:$C$10="Escocia")+($G$5:$G$10="Escocia"))*(($D$5:$D$10)=($F$5:$F$10))) -> 0 | E16: =SUMPRODUCT(($D$5:$D$10<>"")*($F$5:$F$10<>"")*((($C$5:$C$10="Escocia")*(($D$5:$D$10)<($F$5:$F$10)))+(($G$5:$G$10="Escocia")*(($F$5:$F$10)<($D$5:$D$10))))) -> 0 | F16: =SUMPRODUCT(($D$5:$D$10<>"")*($F$5:$F$10<>"")*((($C$5:$C$10="Escocia")*($D$5:$D$10))+(($G$5:$G$10="Escocia")*($F$5:$F$10)))) -> 0 | G16: =SUMPRODUCT(($D$5:$D$10<>"")*($F$5:$F$10<>"")*((($C$5:$C$10="Escocia")*($F$5:$F$10))+(($G$5:$G$10="Escocia")*($D$5:$D$10)))) -> 0 | H16: =F16-G16 -> 0 | I16: =C16*3+D16 -> 0 | K16: =I16*1000000000+H16*1000000+F16*1000+(1) -> 1
A17: Tabla de posiciones (en vivo)
A18: # | B18: Equipo | C18: PJ | D18: PG | E18: PE | F18: PP | G18: GF | H18: GC | I18: DG | J18: Pts | K18: Estado
A19: 1 | B19: =INDEX($A$13:$A$16,MATCH(LARGE($K$13:$K$16,1),$K$13:$K$16,0)) -> Brasil | C19: =INDEX($B$13:$I$16,MATCH(LARGE($K$13:$K$16,1),$K$13:$K$16,0),1) -> 0 | D19: =INDEX($B$13:$I$16,MATCH(LARGE($K$13:$K$16,1),$K$13:$K$16,0),2) -> 0 | E19: =INDEX($B$13:$I$16,MATCH(LARGE($K$13:$K$16,1),$K$13:$K$16,0),3) -> 0 | F19: =INDEX($B$13:$I$16,MATCH(LARGE($K$13:$K$16,1),$K$13:$K$16,0),4) -> 0 | G19: =INDEX($B$13:$I$16,MATCH(LARGE($K$13:$K$16,1),$K$13:$K$16,0),5) -> 0 | H19: =INDEX($B$13:$I$16,MATCH(LARGE($K$13:$K$16,1),$K$13:$K$16,0),6) -> 0 | I19: =INDEX($B$13:$I$16,MATCH(LARGE($K$13:$K$16,1),$K$13:$K$16,0),7) -> 0 | J19: =INDEX($B$13:$I$16,MATCH(LARGE($K$13:$K$16,1),$K$13:$K$16,0),8) -> 0 | K19: ="Clasificado 1ro" -> Clasificado 1ro
A20: 2 | B20: =INDEX($A$13:$A$16,MATCH(LARGE($K$13:$K$16,2),$K$13:$K$16,0)) -> Marruecos | C20: =INDEX($B$13:$I$16,MATCH(LARGE($K$13:$K$16,2),$K$13:$K$16,0),1) -> 0 | D20: =INDEX($B$13:$I$16,MATCH(LARGE($K$13:$K$16,2),$K$13:$K$16,0),2) -> 0 | E20: =INDEX($B$13:$I$16,MATCH(LARGE($K$13:$K$16,2),$K$13:$K$16,0),3) -> 0 | F20: =INDEX($B$13:$I$16,MATCH(LARGE($K$13:$K$16,2),$K$13:$K$16,0),4) -> 0 | G20: =INDEX($B$13:$I$16,MATCH(LARGE($K$13:$K$16,2),$K$13:$K$16,0),5) -> 0 | H20: =INDEX($B$13:$I$16,MATCH(LARGE($K$13:$K$16,2),$K$13:$K$16,0),6) -> 0 | I20: =INDEX($B$13:$I$16,MATCH(LARGE($K$13:$K$16,2),$K$13:$K$16,0),7) -> 0 | J20: =INDEX($B$13:$I$16,MATCH(LARGE($K$13:$K$16,2),$K$13:$K$16,0),8) -> 0 | K20: ="Clasificado 2do" -> Clasificado 2do
A21: 3 | B21: =INDEX($A$13:$A$16,MATCH(LARGE($K$13:$K$16,3),$K$13:$K$16,0)) -> Haiti | C21: =INDEX($B$13:$I$16,MATCH(LARGE($K$13:$K$16,3),$K$13:$K$16,0),1) -> 0 | D21: =INDEX($B$13:$I$16,MATCH(LARGE($K$13:$K$16,3),$K$13:$K$16,0),2) -> 0 | E21: =INDEX($B$13:$I$16,MATCH(LARGE($K$13:$K$16,3),$K$13:$K$16,0),3) -> 0 | F21: =INDEX($B$13:$I$16,MATCH(LARGE($K$13:$K$16,3),$K$13:$K$16,0),4) -> 0 | G21: =INDEX($B$13:$I$16,MATCH(LARGE($K$13:$K$16,3),$K$13:$K$16,0),5) -> 0 | H21: =INDEX($B$13:$I$16,MATCH(LARGE($K$13:$K$16,3),$K$13:$K$16,0),6) -> 0 | I21: =INDEX($B$13:$I$16,MATCH(LARGE($K$13:$K$16,3),$K$13:$K$16,0),7) -> 0 | J21: =INDEX($B$13:$I$16,MATCH(LARGE($K$13:$K$16,3),$K$13:$K$16,0),8) -> 0 | K21: ="3ro (puede avanzar)" -> 3ro (puede avanzar)
A22: 4 | B22: =INDEX($A$13:$A$16,MATCH(LARGE($K$13:$K$16,4),$K$13:$K$16,0)) -> Escocia | C22: =INDEX($B$13:$I$16,MATCH(LARGE($K$13:$K$16,4),$K$13:$K$16,0),1) -> 0 | D22: =INDEX($B$13:$I$16,MATCH(LARGE($K$13:$K$16,4),$K$13:$K$16,0),2) -> 0 | E22: =INDEX($B$13:$I$16,MATCH(LARGE($K$13:$K$16,4),$K$13:$K$16,0),3) -> 0 | F22: =INDEX($B$13:$I$16,MATCH(LARGE($K$13:$K$16,4),$K$13:$K$16,0),4) -> 0 | G22: =INDEX($B$13:$I$16,MATCH(LARGE($K$13:$K$16,4),$K$13:$K$16,0),5) -> 0 | H22: =INDEX($B$13:$I$16,MATCH(LARGE($K$13:$K$16,4),$K$13:$K$16,0),6) -> 0 | I22: =INDEX($B$13:$I$16,MATCH(LARGE($K$13:$K$16,4),$K$13:$K$16,0),7) -> 0 | J22: =INDEX($B$13:$I$16,MATCH(LARGE($K$13:$K$16,4),$K$13:$K$16,0),8) -> 0 | K22: ="Eliminado" -> Eliminado

Sheet Grupo D
A1: Grupo D
A3: Partidos | B3: (las celdas amarillas son editables)
A4: Fecha | B4: Hora (ARG) | C4: Local | D4: Goles | F4: Goles | G4: Visitante | H4: Resultado | I4: Sede
A5: 2026-06-12 | B5: 22:00 | C5: Estados Unidos | E5: - | G5: Paraguay | H5: =IF(OR(D5="",F5=""),"",IF(D5>F5,"L",IF(D5<F5,"V","E"))) | I5: SoFi Stadium, Inglewood
A6: 2026-06-14 | B6: 01:00 | C6: Australia | E6: - | G6: Turquia | H6: =IF(OR(D6="",F6=""),"",IF(D6>F6,"L",IF(D6<F6,"V","E"))) | I6: BC Place, Vancouver
A7: 2026-06-19 | B7: 16:00 | C7: Estados Unidos | E7: - | G7: Australia | H7: =IF(OR(D7="",F7=""),"",IF(D7>F7,"L",IF(D7<F7,"V","E"))) | I7: Lumen Field, Seattle
A8: 2026-06-20 | B8: 00:00 | C8: Turquia | E8: - | G8: Paraguay | H8: =IF(OR(D8="",F8=""),"",IF(D8>F8,"L",IF(D8<F8,"V","E"))) | I8: Levi's Stadium, Santa Clara
A9: 2026-06-25 | B9: 23:00 | C9: Turquia | E9: - | G9: Estados Unidos | H9: =IF(OR(D9="",F9=""),"",IF(D9>F9,"L",IF(D9<F9,"V","E"))) | I9: SoFi Stadium, Inglewood
A10: 2026-06-25 | B10: 23:00 | C10: Paraguay | E10: - | G10: Australia | H10: =IF(OR(D10="",F10=""),"",IF(D10>F10,"L",IF(D10<F10,"V","E"))) | I10: Levi's Stadium, Santa Clara
A11: Tabla (no ordenada)
A12: Equipo | B12: PJ | C12: PG | D12: PE | E12: PP | F12: GF | G12: GC | H12: DG | I12: Pts | K12: Score
A13: Estados Unidos | B13: =SUMPRODUCT((($C$5:$C$10="Estados Unidos")+($G$5:$G$10="Estados Unidos"))*($D$5:$D$10<>"")*($F$5:$F$10<>"")) -> 0 | C13: =SUMPRODUCT(($D$5:$D$10<>"")*($F$5:$F$10<>"")*((($C$5:$C$10="Estados Unidos")*(($D$5:$D$10)>($F$5:$F$10)))+(($G$5:$G$10="Estados Unidos")*(($F$5:$F$10)>($D$5:$D$10))))) -> 0 | D13: =SUMPRODUCT(($D$5:$D$10<>"")*($F$5:$F$10<>"")*(($C$5:$C$10="Estados Unidos")+($G$5:$G$10="Estados Unidos"))*(($D$5:$D$10)=($F$5:$F$10))) -> 0 | E13: =SUMPRODUCT(($D$5:$D$10<>"")*($F$5:$F$10<>"")*((($C$5:$C$10="Estados Unidos")*(($D$5:$D$10)<($F$5:$F$10)))+(($G$5:$G$10="Estados Unidos")*(($F$5:$F$10)<($D$5:$D$10))))) -> 0 | F13: =SUMPRODUCT(($D$5:$D$10<>"")*($F$5:$F$10<>"")*((($C$5:$C$10="Estados Unidos")*($D$5:$D$10))+(($G$5:$G$10="Estados Unidos")*($F$5:$F$10)))) -> 0 | G13: =SUMPRODUCT(($D$5:$D$10<>"")*($F$5:$F$10<>"")*((($C$5:$C$10="Estados Unidos")*($F$5:$F$10))+(($G$5:$G$10="Estados Unidos")*($D$5:$D$10)))) -> 0 | H13: =F13-G13 -> 0 | I13: =C13*3+D13 -> 0 | K13: =I13*1000000000+H13*1000000+F13*1000+(4) -> 4
A14: Paraguay | B14: =SUMPRODUCT((($C$5:$C$10="Paraguay")+($G$5:$G$10="Paraguay"))*($D$5:$D$10<>"")*($F$5:$F$10<>"")) -> 0 | C14: =SUMPRODUCT(($D$5:$D$10<>"")*($F$5:$F$10<>"")*((($C$5:$C$10="Paraguay")*(($D$5:$D$10)>($F$5:$F$10)))+(($G$5:$G$10="Paraguay")*(($F$5:$F$10)>($D$5:$D$10))))) -> 0 | D14: =SUMPRODUCT(($D$5:$D$10<>"")*($F$5:$F$10<>"")*(($C$5:$C$10="Paraguay")+($G$5:$G$10="Paraguay"))*(($D$5:$D$10)=($F$5:$F$10))) -> 0 | E14: =SUMPRODUCT(($D$5:$D$10<>"")*($F$5:$F$10<>"")*((($C$5:$C$10="Paraguay")*(($D$5:$D$10)<($F$5:$F$10)))+(($G$5:$G$10="Paraguay")*(($F$5:$F$10)<($D$5:$D$10))))) -> 0 | F14: =SUMPRODUCT(($D$5:$D$10<>"")*($F$5:$F$10<>"")*((($C$5:$C$10="Paraguay")*($D$5:$D$10))+(($G$5:$G$10="Paraguay")*($F$5:$F$10)))) -> 0 | G14: =SUMPRODUCT(($D$5:$D$10<>"")*($F$5:$F$10<>"")*((($C$5:$C$10="Paraguay")*($F$5:$F$10))+(($G$5:$G$10="Paraguay")*($D$5:$D$10)))) -> 0 | H14: =F14-G14 -> 0 | I14: =C14*3+D14 -> 0 | K14: =I14*1000000000+H14*1000000+F14*1000+(3) -> 3
A15: Australia | B15: =SUMPRODUCT((($C$5:$C$10="Australia")+($G$5:$G$10="Australia"))*($D$5:$D$10<>"")*($F$5:$F$10<>"")) -> 0 | C15: =SUMPRODUCT(($D$5:$D$10<>"")*($F$5:$F$10<>"")*((($C$5:$C$10="Australia")*(($D$5:$D$10)>($F$5:$F$10)))+(($G$5:$G$10="Australia")*(($F$5:$F$10)>($D$5:$D$10))))) -> 0 | D15: =SUMPRODUCT(($D$5:$D$10<>"")*($F$5:$F$10<>"")*(($C$5:$C$10="Australia")+($G$5:$G$10="Australia"))*(($D$5:$D$10)=($F$5:$F$10))) -> 0 | E15: =SUMPRODUCT(($D$5:$D$10<>"")*($F$5:$F$10<>"")*((($C$5:$C$10="Australia")*(($D$5:$D$10)<($F$5:$F$10)))+(($G$5:$G$10="Australia")*(($F$5:$F$10)<($D$5:$D$10))))) -> 0 | F15: =SUMPRODUCT(($D$5:$D$10<>"")*($F$5:$F$10<>"")*((($C$5:$C$10="Australia")*($D$5:$D$10))+(($G$5:$G$10="Australia")*($F$5:$F$10)))) -> 0 | G15: =SUMPRODUCT(($D$5:$D$10<>"")*($F$5:$F$10<>"")*((($C$5:$C$10="Australia")*($F$5:$F$10))+(($G$5:$G$10="Australia")*($D$5:$D$10)))) -> 0 | H15: =F15-G15 -> 0 | I15: =C15*3+D15 -> 0 | K15: =I15*1000000000+H15*1000000+F15*1000+(2) -> 2
A16: Turquia | B16: =SUMPRODUCT((($C$5:$C$10="Turquia")+($G$5:$G$10="Turquia"))*($D$5:$D$10<>"")*($F$5:$F$10<>"")) -> 0 | C16: =SUMPRODUCT(($D$5:$D$10<>"")*($F$5:$F$10<>"")*((($C$5:$C$10="Turquia")*(($D$5:$D$10)>($F$5:$F$10)))+(($G$5:$G$10="Turquia")*(($F$5:$F$10)>($D$5:$D$10))))) -> 0 | D16: =SUMPRODUCT(($D$5:$D$10<>"")*($F$5:$F$10<>"")*(($C$5:$C$10="Turquia")+($G$5:$G$10="Turquia"))*(($D$5:$D$10)=($F$5:$F$10))) -> 0 | E16: =SUMPRODUCT(($D$5:$D$10<>"")*($F$5:$F$10<>"")*((($C$5:$C$10="Turquia")*(($D$5:$D$10)<($F$5:$F$10)))+(($G$5:$G$10="Turquia")*(($F$5:$F$10)<($D$5:$D$10))))) -> 0 | F16: =SUMPRODUCT(($D$5:$D$10<>"")*($F$5:$F$10<>"")*((($C$5:$C$10="Turquia")*($D$5:$D$10))+(($G$5:$G$10="Turquia")*($F$5:$F$10)))) -> 0 | G16: =SUMPRODUCT(($D$5:$D$10<>"")*($F$5:$F$10<>"")*((($C$5:$C$10="Turquia")*($F$5:$F$10))+(($G$5:$G$10="Turquia")*($D$5:$D$10)))) -> 0 | H16: =F16-G16 -> 0 | I16: =C16*3+D16 -> 0 | K16: =I16*1000000000+H16*1000000+F16*1000+(1) -> 1
A17: Tabla de posiciones (en vivo)
A18: # | B18: Equipo | C18: PJ | D18: PG | E18: PE | F18: PP | G18: GF | H18: GC | I18: DG | J18: Pts | K18: Estado
A19: 1 | B19: =INDEX($A$13:$A$16,MATCH(LARGE($K$13:$K$16,1),$K$13:$K$16,0)) -> Estados Unidos | C19: =INDEX($B$13:$I$16,MATCH(LARGE($K$13:$K$16,1),$K$13:$K$16,0),1) -> 0 | D19: =INDEX($B$13:$I$16,MATCH(LARGE($K$13:$K$16,1),$K$13:$K$16,0),2) -> 0 | E19: =INDEX($B$13:$I$16,MATCH(LARGE($K$13:$K$16,1),$K$13:$K$16,0),3) -> 0 | F19: =INDEX($B$13:$I$16,MATCH(LARGE($K$13:$K$16,1),$K$13:$K$16,0),4) -> 0 | G19: =INDEX($B$13:$I$16,MATCH(LARGE($K$13:$K$16,1),$K$13:$K$16,0),5) -> 0 | H19: =INDEX($B$13:$I$16,MATCH(LARGE($K$13:$K$16,1),$K$13:$K$16,0),6) -> 0 | I19: =INDEX($B$13:$I$16,MATCH(LARGE($K$13:$K$16,1),$K$13:$K$16,0),7) -> 0 | J19: =INDEX($B$13:$I$16,MATCH(LARGE($K$13:$K$16,1),$K$13:$K$16,0),8) -> 0 | K19: ="Clasificado 1ro" -> Clasificado 1ro
A20: 2 | B20: =INDEX($A$13:$A$16,MATCH(LARGE($K$13:$K$16,2),$K$13:$K$16,0)) -> Paraguay | C20: =INDEX($B$13:$I$16,MATCH(LARGE($K$13:$K$16,2),$K$13:$K$16,0),1) -> 0 | D20: =INDEX($B$13:$I$16,MATCH(LARGE($K$13:$K$16,2),$K$13:$K$16,0),2) -> 0 | E20: =INDEX($B$13:$I$16,MATCH(LARGE($K$13:$K$16,2),$K$13:$K$16,0),3) -> 0 | F20: =INDEX($B$13:$I$16,MATCH(LARGE($K$13:$K$16,2),$K$13:$K$16,0),4) -> 0 | G20: =INDEX($B$13:$I$16,MATCH(LARGE($K$13:$K$16,2),$K$13:$K$16,0),5) -> 0 | H20: =INDEX($B$13:$I$16,MATCH(LARGE($K$13:$K$16,2),$K$13:$K$16,0),6) -> 0 | I20: =INDEX($B$13:$I$16,MATCH(LARGE($K$13:$K$16,2),$K$13:$K$16,0),7) -> 0 | J20: =INDEX($B$13:$I$16,MATCH(LARGE($K$13:$K$16,2),$K$13:$K$16,0),8) -> 0 | K20: ="Clasificado 2do" -> Clasificado 2do
A21: 3 | B21: =INDEX($A$13:$A$16,MATCH(LARGE($K$13:$K$16,3),$K$13:$K$16,0)) -> Australia | C21: =INDEX($B$13:$I$16,MATCH(LARGE($K$13:$K$16,3),$K$13:$K$16,0),1) -> 0 | D21: =INDEX($B$13:$I$16,MATCH(LARGE($K$13:$K$16,3),$K$13:$K$16,0),2) -> 0 | E21: =INDEX($B$13:$I$16,MATCH(LARGE($K$13:$K$16,3),$K$13:$K$16,0),3) -> 0 | F21: =INDEX($B$13:$I$16,MATCH(LARGE($K$13:$K$16,3),$K$13:$K$16,0),4) -> 0 | G21: =INDEX($B$13:$I$16,MATCH(LARGE($K$13:$K$16,3),$K$13:$K$16,0),5) -> 0 | H21: =INDEX($B$13:$I$16,MATCH(LARGE($K$13:$K$16,3),$K$13:$K$16,0),6) -> 0 | I21: =INDEX($B$13:$I$16,MATCH(LARGE($K$13:$K$16,3),$K$13:$K$16,0),7) -> 0 | J21: =INDEX($B$13:$I$16,MATCH(LARGE($K$13:$K$16,3),$K$13:$K$16,0),8) -> 0 | K21: ="3ro (puede avanzar)" -> 3ro (puede avanzar)
A22: 4 | B22: =INDEX($A$13:$A$16,MATCH(LARGE($K$13:$K$16,4),$K$13:$K$16,0)) -> Turquia | C22: =INDEX($B$13:$I$16,MATCH(LARGE($K$13:$K$16,4),$K$13:$K$16,0),1) -> 0 | D22: =INDEX($B$13:$I$16,MATCH(LARGE($K$13:$K$16,4),$K$13:$K$16,0),2) -> 0 | E22: =INDEX($B$13:$I$16,MATCH(LARGE($K$13:$K$16,4),$K$13:$K$16,0),3) -> 0 | F22: =INDEX($B$13:$I$16,MATCH(LARGE($K$13:$K$16,4),$K$13:$K$16,0),4) -> 0 | G22: =INDEX($B$13:$I$16,MATCH(LARGE($K$13:$K$16,4),$K$13:$K$16,0),5) -> 0 | H22: =INDEX($B$13:$I$16,MATCH(LARGE($K$13:$K$16,4),$K$13:$K$16,0),6) -> 0 | I22: =INDEX($B$13:$I$16,MATCH(LARGE($K$13:$K$16,4),$K$13:$K$16,0),7) -> 0 | J22: =INDEX($B$13:$I$16,MATCH(LARGE($K$13:$K$16,4),$K$13:$K$16,0),8) -> 0 | K22: ="Eliminado" -> Eliminado

Sheet Grupo E
A1: Grupo E
A3: Partidos | B3: (las celdas amarillas son editables)
A4: Fecha | B4: Hora (ARG) | C4: Local | D4: Goles | F4: Goles | G4: Visitante | H4: Resultado | I4: Sede
A5: 2026-06-14 | B5: 14:00 | C5: Alemania | E5: - | G5: Curazao | H5: =IF(OR(D5="",F5=""),"",IF(D5>F5,"L",IF(D5<F5,"V","E"))) | I5: NRG Stadium, Houston
A6: 2026-06-14 | B6: 20:00 | C6: Costa de Marfil | E6: - | G6: Ecuador | H6: =IF(OR(D6="",F6=""),"",IF(D6>F6,"L",IF(D6<F6,"V","E"))) | I6: Lincoln Financial Field, Philadelphia
A7: 2026-06-20 | B7: 17:00 | C7: Alemania | E7: - | G7: Costa de Marfil | H7: =IF(OR(D7="",F7=""),"",IF(D7>F7,"L",IF(D7<F7,"V","E"))) | I7: BMO Field, Toronto
A8: 2026-06-20 | B8: 21:00 | C8: Ecuador | E8: - | G8: Curazao | H8: =IF(OR(D8="",F8=""),"",IF(D8>F8,"L",IF(D8<F8,"V","E"))) | I8: Arrowhead Stadium, Kansas City
A9: 2026-06-25 | B9: 17:00 | C9: Curazao | E9: - | G9: Costa de Marfil | H9: =IF(OR(D9="",F9=""),"",IF(D9>F9,"L",IF(D9<F9,"V","E"))) | I9: Lincoln Financial Field, Philadelphia
A10: 2026-06-25 | B10: 17:00 | C10: Ecuador | E10: - | G10: Alemania | H10: =IF(OR(D10="",F10=""),"",IF(D10>F10,"L",IF(D10<F10,"V","E"))) | I10: MetLife Stadium, East Rutherford
A11: Tabla (no ordenada)
A12: Equipo | B12: PJ | C12: PG | D12: PE | E12: PP | F12: GF | G12: GC | H12: DG | I12: Pts | K12: Score
A13: Alemania | B13: =SUMPRODUCT((($C$5:$C$10="Alemania")+($G$5:$G$10="Alemania"))*($D$5:$D$10<>"")*($F$5:$F$10<>"")) -> 0 | C13: =SUMPRODUCT(($D$5:$D$10<>"")*($F$5:$F$10<>"")*((($C$5:$C$10="Alemania")*(($D$5:$D$10)>($F$5:$F$10)))+(($G$5:$G$10="Alemania")*(($F$5:$F$10)>($D$5:$D$10))))) -> 0 | D13: =SUMPRODUCT(($D$5:$D$10<>"")*($F$5:$F$10<>"")*(($C$5:$C$10="Alemania")+($G$5:$G$10="Alemania"))*(($D$5:$D$10)=($F$5:$F$10))) -> 0 | E13: =SUMPRODUCT(($D$5:$D$10<>"")*($F$5:$F$10<>"")*((($C$5:$C$10="Alemania")*(($D$5:$D$10)<($F$5:$F$10)))+(($G$5:$G$10="Alemania")*(($F$5:$F$10)<($D$5:$D$10))))) -> 0 | F13: =SUMPRODUCT(($D$5:$D$10<>"")*($F$5:$F$10<>"")*((($C$5:$C$10="Alemania")*($D$5:$D$10))+(($G$5:$G$10="Alemania")*($F$5:$F$10)))) -> 0 | G13: =SUMPRODUCT(($D$5:$D$10<>"")*($F$5:$F$10<>"")*((($C$5:$C$10="Alemania")*($F$5:$F$10))+(($G$5:$G$10="Alemania")*($D$5:$D$10)))) -> 0 | H13: =F13-G13 -> 0 | I13: =C13*3+D13 -> 0 | K13: =I13*1000000000+H13*1000000+F13*1000+(4) -> 4
A14: Curazao | B14: =SUMPRODUCT((($C$5:$C$10="Curazao")+($G$5:$G$10="Curazao"))*($D$5:$D$10<>"")*($F$5:$F$10<>"")) -> 0 | C14: =SUMPRODUCT(($D$5:$D$10<>"")*($F$5:$F$10<>"")*((($C$5:$C$10="Curazao")*(($D$5:$D$10)>($F$5:$F$10)))+(($G$5:$G$10="Curazao")*(($F$5:$F$10)>($D$5:$D$10))))) -> 0 | D14: =SUMPRODUCT(($D$5:$D$10<>"")*($F$5:$F$10<>"")*(($C$5:$C$10="Curazao")+($G$5:$G$10="Curazao"))*(($D$5:$D$10)=($F$5:$F$10))) -> 0 | E14: =SUMPRODUCT(($D$5:$D$10<>"")*($F$5:$F$10<>"")*((($C$5:$C$10="Curazao")*(($D$5:$D$10)<($F$5:$F$10)))+(($G$5:$G$10="Curazao")*(($F$5:$F$10)<($D$5:$D$10))))) -> 0 | F14: =SUMPRODUCT(($D$5:$D$10<>"")*($F$5:$F$10<>"")*((($C$5:$C$10="Curazao")*($D$5:$D$10))+(($G$5:$G$10="Curazao")*($F$5:$F$10)))) -> 0 | G14: =SUMPRODUCT(($D$5:$D$10<>"")*($F$5:$F$10<>"")*((($C$5:$C$10="Curazao")*($F$5:$F$10))+(($G$5:$G$10="Curazao")*($D$5:$D$10)))) -> 0 | H14: =F14-G14 -> 0 | I14: =C14*3+D14 -> 0 | K14: =I14*1000000000+H14*1000000+F14*1000+(3) -> 3
A15: Costa de Marfil | B15: =SUMPRODUCT((($C$5:$C$10="Costa de Marfil")+($G$5:$G$10="Costa de Marfil"))*($D$5:$D$10<>"")*($F$5:$F$10<>"")) -> 0 | C15: =SUMPRODUCT(($D$5:$D$10<>"")*($F$5:$F$10<>"")*((($C$5:$C$10="Costa de Marfil")*(($D$5:$D$10)>($F$5:$F$10)))+(($G$5:$G$10="Costa de Marfil")*(($F$5:$F$10)>($D$5:$D$10))))) -> 0 | D15: =SUMPRODUCT(($D$5:$D$10<>"")*($F$5:$F$10<>"")*(($C$5:$C$10="Costa de Marfil")+($G$5:$G$10="Costa de Marfil"))*(($D$5:$D$10)=($F$5:$F$10))) -> 0 | E15: =SUMPRODUCT(($D$5:$D$10<>"")*($F$5:$F$10<>"")*((($C$5:$C$10="Costa de Marfil")*(($D$5:$D$10)<($F$5:$F$10)))+(($G$5:$G$10="Costa de Marfil")*(($F$5:$F$10)<($D$5:$D$10))))) -> 0 | F15: =SUMPRODUCT(($D$5:$D$10<>"")*($F$5:$F$10<>"")*((($C$5:$C$10="Costa de Marfil")*($D$5:$D$10))+(($G$5:$G$10="Costa de Marfil")*($F$5:$F$10)))) -> 0 | G15: =SUMPRODUCT(($D$5:$D$10<>"")*($F$5:$F$10<>"")*((($C$5:$C$10="Costa de Marfil")*($F$5:$F$10))+(($G$5:$G$10="Costa de Marfil")*($D$5:$D$10)))) -> 0 | H15: =F15-G15 -> 0 | I15: =C15*3+D15 -> 0 | K15: =I15*1000000000+H15*1000000+F15*1000+(2) -> 2
A16: Ecuador | B16: =SUMPRODUCT((($C$5:$C$10="Ecuador")+($G$5:$G$10="Ecuador"))*($D$5:$D$10<>"")*($F$5:$F$10<>"")) -> 0 | C16: =SUMPRODUCT(($D$5:$D$10<>"")*($F$5:$F$10<>"")*((($C$5:$C$10="Ecuador")*(($D$5:$D$10)>($F$5:$F$10)))+(($G$5:$G$10="Ecuador")*(($F$5:$F$10)>($D$5:$D$10))))) -> 0 | D16: =SUMPRODUCT(($D$5:$D$10<>"")*($F$5:$F$10<>"")*(($C$5:$C$10="Ecuador")+($G$5:$G$10="Ecuador"))*(($D$5:$D$10)=($F$5:$F$10))) -> 0 | E16: =SUMPRODUCT(($D$5:$D$10<>"")*($F$5:$F$10<>"")*((($C$5:$C$10="Ecuador")*(($D$5:$D$10)<($F$5:$F$10)))+(($G$5:$G$10="Ecuador")*(($F$5:$F$10)<($D$5:$D$10))))) -> 0 | F16: =SUMPRODUCT(($D$5:$D$10<>"")*($F$5:$F$10<>"")*((($C$5:$C$10="Ecuador")*($D$5:$D$10))+(($G$5:$G$10="Ecuador")*($F$5:$F$10)))) -> 0 | G16: =SUMPRODUCT(($D$5:$D$10<>"")*($F$5:$F$10<>"")*((($C$5:$C$10="Ecuador")*($F$5:$F$10))+(($G$5:$G$10="Ecuador")*($D$5:$D$10)))) -> 0 | H16: =F16-G16 -> 0 | I16: =C16*3+D16 -> 0 | K16: =I16*1000000000+H16*1000000+F16*1000+(1) -> 1
A17: Tabla de posiciones (en vivo)
A18: # | B18: Equipo | C18: PJ | D18: PG | E18: PE | F18: PP | G18: GF | H18: GC | I18: DG | J18: Pts | K18: Estado
A19: 1 | B19: =INDEX($A$13:$A$16,MATCH(LARGE($K$13:$K$16,1),$K$13:$K$16,0)) -> Alemania | C19: =INDEX($B$13:$I$16,MATCH(LARGE($K$13:$K$16,1),$K$13:$K$16,0),1) -> 0 | D19: =INDEX($B$13:$I$16,MATCH(LARGE($K$13:$K$16,1),$K$13:$K$16,0),2) -> 0 | E19: =INDEX($B$13:$I$16,MATCH(LARGE($K$13:$K$16,1),$K$13:$K$16,0),3) -> 0 | F19: =INDEX($B$13:$I$16,MATCH(LARGE($K$13:$K$16,1),$K$13:$K$16,0),4) -> 0 | G19: =INDEX($B$13:$I$16,MATCH(LARGE($K$13:$K$16,1),$K$13:$K$16,0),5) -> 0 | H19: =INDEX($B$13:$I$16,MATCH(LARGE($K$13:$K$16,1),$K$13:$K$16,0),6) -> 0 | I19: =INDEX($B$13:$I$16,MATCH(LARGE($K$13:$K$16,1),$K$13:$K$16,0),7) -> 0 | J19: =INDEX($B$13:$I$16,MATCH(LARGE($K$13:$K$16,1),$K$13:$K$16,0),8) -> 0 | K19: ="Clasificado 1ro" -> Clasificado 1ro
A20: 2 | B20: =INDEX($A$13:$A$16,MATCH(LARGE($K$13:$K$16,2),$K$13:$K$16,0)) -> Curazao | C20: =INDEX($B$13:$I$16,MATCH(LARGE($K$13:$K$16,2),$K$13:$K$16,0),1) -> 0 | D20: =INDEX($B$13:$I$16,MATCH(LARGE($K$13:$K$16,2),$K$13:$K$16,0),2) -> 0 | E20: =INDEX($B$13:$I$16,MATCH(LARGE($K$13:$K$16,2),$K$13:$K$16,0),3) -> 0 | F20: =INDEX($B$13:$I$16,MATCH(LARGE($K$13:$K$16,2),$K$13:$K$16,0),4) -> 0 | G20: =INDEX($B$13:$I$16,MATCH(LARGE($K$13:$K$16,2),$K$13:$K$16,0),5) -> 0 | H20: =INDEX($B$13:$I$16,MATCH(LARGE($K$13:$K$16,2),$K$13:$K$16,0),6) -> 0 | I20: =INDEX($B$13:$I$16,MATCH(LARGE($K$13:$K$16,2),$K$13:$K$16,0),7) -> 0 | J20: =INDEX($B$13:$I$16,MATCH(LARGE($K$13:$K$16,2),$K$13:$K$16,0),8) -> 0 | K20: ="Clasificado 2do" -> Clasificado 2do
A21: 3 | B21: =INDEX($A$13:$A$16,MATCH(LARGE($K$13:$K$16,3),$K$13:$K$16,0)) -> Costa de Marfil | C21: =INDEX($B$13:$I$16,MATCH(LARGE($K$13:$K$16,3),$K$13:$K$16,0),1) -> 0 | D21: =INDEX($B$13:$I$16,MATCH(LARGE($K$13:$K$16,3),$K$13:$K$16,0),2) -> 0 | E21: =INDEX($B$13:$I$16,MATCH(LARGE($K$13:$K$16,3),$K$13:$K$16,0),3) -> 0 | F21: =INDEX($B$13:$I$16,MATCH(LARGE($K$13:$K$16,3),$K$13:$K$16,0),4) -> 0 | G21: =INDEX($B$13:$I$16,MATCH(LARGE($K$13:$K$16,3),$K$13:$K$16,0),5) -> 0 | H21: =INDEX($B$13:$I$16,MATCH(LARGE($K$13:$K$16,3),$K$13:$K$16,0),6) -> 0 | I21: =INDEX($B$13:$I$16,MATCH(LARGE($K$13:$K$16,3),$K$13:$K$16,0),7) -> 0 | J21: =INDEX($B$13:$I$16,MATCH(LARGE($K$13:$K$16,3),$K$13:$K$16,0),8) -> 0 | K21: ="3ro (puede avanzar)" -> 3ro (puede avanzar)
A22: 4 | B22: =INDEX($A$13:$A$16,MATCH(LARGE($K$13:$K$16,4),$K$13:$K$16,0)) -> Ecuador | C22: =INDEX($B$13:$I$16,MATCH(LARGE($K$13:$K$16,4),$K$13:$K$16,0),1) -> 0 | D22: =INDEX($B$13:$I$16,MATCH(LARGE($K$13:$K$16,4),$K$13:$K$16,0),2) -> 0 | E22: =INDEX($B$13:$I$16,MATCH(LARGE($K$13:$K$16,4),$K$13:$K$16,0),3) -> 0 | F22: =INDEX($B$13:$I$16,MATCH(LARGE($K$13:$K$16,4),$K$13:$K$16,0),4) -> 0 | G22: =INDEX($B$13:$I$16,MATCH(LARGE($K$13:$K$16,4),$K$13:$K$16,0),5) -> 0 | H22: =INDEX($B$13:$I$16,MATCH(LARGE($K$13:$K$16,4),$K$13:$K$16,0),6) -> 0 | I22: =INDEX($B$13:$I$16,MATCH(LARGE($K$13:$K$16,4),$K$13:$K$16,0),7) -> 0 | J22: =INDEX($B$13:$I$16,MATCH(LARGE($K$13:$K$16,4),$K$13:$K$16,0),8) -> 0 | K22: ="Eliminado" -> Eliminado

Sheet Grupo F
A1: Grupo F
A3: Partidos | B3: (las celdas amarillas son editables)
A4: Fecha | B4: Hora (ARG) | C4: Local | D4: Goles | F4: Goles | G4: Visitante | H4: Resultado | I4: Sede
A5: 2026-06-14 | B5: 17:00 | C5: Paises Bajos | E5: - | G5: Japon | H5: =IF(OR(D5="",F5=""),"",IF(D5>F5,"L",IF(D5<F5,"V","E"))) | I5: AT&T Stadium, Arlington
A6: 2026-06-14 | B6: 23:00 | C6: Suecia | E6: - | G6: Tunez | H6: =IF(OR(D6="",F6=""),"",IF(D6>F6,"L",IF(D6<F6,"V","E"))) | I6: Estadio BBVA, Monterrey
A7: 2026-06-20 | B7: 14:00 | C7: Paises Bajos | E7: - | G7: Suecia | H7: =IF(OR(D7="",F7=""),"",IF(D7>F7,"L",IF(D7<F7,"V","E"))) | I7: NRG Stadium, Houston
A8: 2026-06-21 | B8: 01:00 | C8: Tunez | E8: - | G8: Japon | H8: =IF(OR(D8="",F8=""),"",IF(D8>F8,"L",IF(D8<F8,"V","E"))) | I8: Estadio BBVA, Monterrey
A9: 2026-06-25 | B9: 20:00 | C9: Japon | E9: - | G9: Suecia | H9: =IF(OR(D9="",F9=""),"",IF(D9>F9,"L",IF(D9<F9,"V","E"))) | I9: AT&T Stadium, Arlington
A10: 2026-06-25 | B10: 20:00 | C10: Tunez | E10: - | G10: Paises Bajos | H10: =IF(OR(D10="",F10=""),"",IF(D10>F10,"L",IF(D10<F10,"V","E"))) | I10: Arrowhead Stadium, Kansas City
A11: Tabla (no ordenada)
A12: Equipo | B12: PJ | C12: PG | D12: PE | E12: PP | F12: GF | G12: GC | H12: DG | I12: Pts | K12: Score
